2025-07-17 13:57:39,543 - INFO - üöÄ Starting stealth job application bot
2025-07-17 13:57:41,373 - INFO - üìÇ Loading jobs from output/final_ml_jobs.csv
2025-07-17 13:57:41,379 - INFO -    üìä Total jobs in file: 635
2025-07-17 13:57:41,381 - INFO -    üéØ Easy Apply jobs: 635
2025-07-17 13:57:41,381 - INFO -    ‚è≥ Jobs to process: 10 (status: pending)
2025-07-17 13:57:41,382 - INFO - üé≤ Will attempt 10 applications this run (target: 80)
2025-07-17 13:57:41,382 - INFO - üîë Logging into Dice...
2025-07-17 13:57:44,277 - INFO - ‚úÖ Login successful
2025-07-17 13:57:46,313 - INFO - üîÑ Starting job applications...
2025-07-17 13:57:46,314 - INFO - üéØ [1/10] Applying to: GenAI Python Lead Developer - LINK: https://www.dice.com/job-detail/85bbbde4-1ba7-4163-9050-0b74ebf3827c
2025-07-17 13:59:58,191 - ERROR -    ‚ùå Cannot click first NEXT button: HTTPConnectionPool(host='localhost', port=59875): Read timed out. (read timeout=120)
2025-07-17 14:02:09,502 - INFO - üéØ [2/10] Applying to: Contact Center Data / AI Architect (OnPrem / CCaaS) (450751) - LINK: https://www.dice.com/job-detail/3788b221-c4a5-4ffe-af38-8a75aa46a8a2
2025-07-17 14:03:13,731 - ERROR -    ‚ùå Cannot click apply button: Message: element not interactable
  (Session info: chrome=138.0.7204.100); For documentation on this error, please visit: https://www.selenium.dev/documentation/webdriver/troubleshooting/errors#elementnotinteractableexception
Stacktrace:
#0 0x558f539727da <unknown>
#1 0x558f53417133 <unknown>
#2 0x558f5346a00e <unknown>
#3 0x558f5345d0ea <unknown>
#4 0x558f5348e8b2 <unknown>
#5 0x558f5345ca6a <unknown>
#6 0x558f5348ea7e <unknown>
#7 0x558f534b471c <unknown>
#8 0x558f5348e683 <unknown>
#9 0x558f5345ab5b <unknown>
#10 0x558f5345bf31 <unknown>
#11 0x558f5393772b <unknown>
#12 0x558f5393b534 <unknown>
#13 0x558f5391e229 <unknown>
#14 0x558f5393c0d8 <unknown>
#15 0x558f5390261f <unknown>
#16 0x558f5395fdd8 <unknown>
#17 0x558f5395ffb6 <unknown>
#18 0x558f53971af6 <unknown>
#19 0x7fc075a9caa4 <unknown>
#20 0x7fc075b29c3c <unknown>

2025-07-17 14:03:24,382 - INFO - üéØ [3/10] Applying to: Senior AI Developer (Contract) Microsoft Copilot Studio - LINK: https://www.dice.com/job-detail/d5431aac-df3d-43e1-86d7-f8004b3b7497
2025-07-17 14:03:39,254 - ERROR -    ‚ùå Cannot click apply button: Message: element not interactable
  (Session info: chrome=138.0.7204.100); For documentation on this error, please visit: https://www.selenium.dev/documentation/webdriver/troubleshooting/errors#elementnotinteractableexception
Stacktrace:
#0 0x558f539727da <unknown>
#1 0x558f53417133 <unknown>
#2 0x558f5346a00e <unknown>
#3 0x558f5345d0ea <unknown>
#4 0x558f5348e8b2 <unknown>
#5 0x558f5345ca6a <unknown>
#6 0x558f5348ea7e <unknown>
#7 0x558f534b471c <unknown>
#8 0x558f5348e683 <unknown>
#9 0x558f5345ab5b <unknown>
#10 0x558f5345bf31 <unknown>
#11 0x558f5393772b <unknown>
#12 0x558f5393b534 <unknown>
#13 0x558f5391e229 <unknown>
#14 0x558f5393c0d8 <unknown>
#15 0x558f5390261f <unknown>
#16 0x558f5395fdd8 <unknown>
#17 0x558f5395ffb6 <unknown>
#18 0x558f53971af6 <unknown>
#19 0x7fc075a9caa4 <unknown>
#20 0x7fc075b29c3c <unknown>

2025-07-17 14:03:49,423 - INFO - üéØ [4/10] Applying to: GENAI Adoption Manager - LINK: https://www.dice.com/job-detail/99d3a7cc-5741-492e-a047-3fb534ed7264
2025-07-17 14:04:05,816 - ERROR -    ‚ùå Cannot click apply button: Message: element not interactable
  (Session info: chrome=138.0.7204.100); For documentation on this error, please visit: https://www.selenium.dev/documentation/webdriver/troubleshooting/errors#elementnotinteractableexception
Stacktrace:
#0 0x558f539727da <unknown>
#1 0x558f53417133 <unknown>
#2 0x558f5346a00e <unknown>
#3 0x558f5345d0ea <unknown>
#4 0x558f5348e8b2 <unknown>
#5 0x558f5345ca6a <unknown>
#6 0x558f5348ea7e <unknown>
#7 0x558f534b471c <unknown>
#8 0x558f5348e683 <unknown>
#9 0x558f5345ab5b <unknown>
#10 0x558f5345bf31 <unknown>
#11 0x558f5393772b <unknown>
#12 0x558f5393b534 <unknown>
#13 0x558f5391e229 <unknown>
#14 0x558f5393c0d8 <unknown>
#15 0x558f5390261f <unknown>
#16 0x558f5395fdd8 <unknown>
#17 0x558f5395ffb6 <unknown>
#18 0x558f53971af6 <unknown>
#19 0x7fc075a9caa4 <unknown>
#20 0x7fc075b29c3c <unknown>

2025-07-17 14:04:14,613 - INFO - üéØ [5/10] Applying to: Data Scientist - LINK: https://www.dice.com/job-detail/cf67f35d-5047-4af5-964a-70556a611989
2025-07-17 14:04:32,722 - INFO -    ‚úÖ Successfully applied!
2025-07-17 14:06:40,542 - INFO - üéØ [6/10] Applying to: Data Scientist -- Azure and ML!- W2 (H1B/OPT) Accepted - LINK: https://www.dice.com/job-detail/0bdb290b-d40a-4d84-87e1-c516b92667a4
2025-07-17 14:08:40,616 - ERROR -    ‚ùå Application failed: HTTPConnectionPool(host='localhost', port=59875): Read timed out. (read timeout=120)
2025-07-17 14:08:40,616 - ERROR - Full error for Data Scientist -- Azure and ML!- W2 (H1B/OPT) Accepted:
Traceback (most recent call last):
  File "/opt/hostedtoolcache/Python/3.10.18/x64/lib/python3.10/site-packages/urllib3/connectionpool.py", line 534, in _make_request
    response = conn.getresponse()
  File "/opt/hostedtoolcache/Python/3.10.18/x64/lib/python3.10/site-packages/urllib3/connection.py", line 565, in getresponse
    httplib_response = super().getresponse()
  File "/opt/hostedtoolcache/Python/3.10.18/x64/lib/python3.10/http/client.py", line 1375, in getresponse
    response.begin()
  File "/opt/hostedtoolcache/Python/3.10.18/x64/lib/python3.10/http/client.py", line 318, in begin
    version, status, reason = self._read_status()
  File "/opt/hostedtoolcache/Python/3.10.18/x64/lib/python3.10/http/client.py", line 279, in _read_status
    line = str(self.fp.readline(_MAXLINE + 1), "iso-8859-1")
  File "/opt/hostedtoolcache/Python/3.10.18/x64/lib/python3.10/socket.py", line 717, in readinto
    return self._sock.recv_into(b)
TimeoutError: timed out

The above exception was the direct cause of the following exception:

Traceback (most recent call last):
  File "/home/runner/work/Applier-Workflow/Applier-Workflow/scripts/src/stealth_apply.py", line 145, in easy_apply
    driver.get(job_link)
  File "/opt/hostedtoolcache/Python/3.10.18/x64/lib/python3.10/site-packages/undetected_chromedriver/__init__.py", line 496, in get_wrapped
    if self.execute_script("return navigator.webdriver"):
  File "/opt/hostedtoolcache/Python/3.10.18/x64/lib/python3.10/site-packages/selenium/webdriver/remote/webdriver.py", line 551, in execute_script
    return self.execute(command, {"script": script, "args": converted_args})["value"]
  File "/opt/hostedtoolcache/Python/3.10.18/x64/lib/python3.10/site-packages/selenium/webdriver/remote/webdriver.py", line 451, in execute
    response = cast(RemoteConnection, self.command_executor).execute(driver_command, params)
  File "/opt/hostedtoolcache/Python/3.10.18/x64/lib/python3.10/site-packages/selenium/webdriver/remote/remote_connection.py", line 404, in execute
    return self._request(command_info[0], url, body=data)
  File "/opt/hostedtoolcache/Python/3.10.18/x64/lib/python3.10/site-packages/selenium/webdriver/remote/remote_connection.py", line 428, in _request
    response = self._conn.request(method, url, body=body, headers=headers, timeout=self._client_config.timeout)
  File "/opt/hostedtoolcache/Python/3.10.18/x64/lib/python3.10/site-packages/urllib3/_request_methods.py", line 143, in request
    return self.request_encode_body(
  File "/opt/hostedtoolcache/Python/3.10.18/x64/lib/python3.10/site-packages/urllib3/_request_methods.py", line 278, in request_encode_body
    return self.urlopen(method, url, **extra_kw)
  File "/opt/hostedtoolcache/Python/3.10.18/x64/lib/python3.10/site-packages/urllib3/poolmanager.py", line 459, in urlopen
    response = conn.urlopen(method, u.request_uri, **kw)
  File "/opt/hostedtoolcache/Python/3.10.18/x64/lib/python3.10/site-packages/urllib3/connectionpool.py", line 841, in urlopen
    retries = retries.increment(
  File "/opt/hostedtoolcache/Python/3.10.18/x64/lib/python3.10/site-packages/urllib3/util/retry.py", line 474, in increment
    raise reraise(type(error), error, _stacktrace)
  File "/opt/hostedtoolcache/Python/3.10.18/x64/lib/python3.10/site-packages/urllib3/util/util.py", line 39, in reraise
    raise value
  File "/opt/hostedtoolcache/Python/3.10.18/x64/lib/python3.10/site-packages/urllib3/connectionpool.py", line 787, in urlopen
    response = self._make_request(
  File "/opt/hostedtoolcache/Python/3.10.18/x64/lib/python3.10/site-packages/urllib3/connectionpool.py", line 536, in _make_request
    self._raise_timeout(err=e, url=url, timeout_value=read_timeout)
  File "/opt/hostedtoolcache/Python/3.10.18/x64/lib/python3.10/site-packages/urllib3/connectionpool.py", line 367, in _raise_timeout
    raise ReadTimeoutError(
urllib3.exceptions.ReadTimeoutError: HTTPConnectionPool(host='localhost', port=59875): Read timed out. (read timeout=120)
2025-07-17 14:09:41,618 - INFO - üéØ [7/10] Applying to: Data AI Engineer - LINK: https://www.dice.com/job-detail/063d296f-5de1-4d94-a4bf-803088425a69
2025-07-17 14:09:57,760 - INFO -    ‚úÖ Successfully applied!
2025-07-17 14:12:05,662 - INFO - üéØ [8/10] Applying to: AI/ML Engineer - AI, Ml, Google Cloud Platform, GKE experience - LINK: https://www.dice.com/job-detail/d42cb8fa-559d-493a-8b6f-ec489a5d5e04
2025-07-17 14:14:05,724 - ERROR -    ‚ùå Application failed: HTTPConnectionPool(host='localhost', port=59875): Read timed out. (read timeout=120)
2025-07-17 14:14:05,724 - ERROR - Full error for AI/ML Engineer - AI, Ml, Google Cloud Platform, GKE experience:
Traceback (most recent call last):
  File "/opt/hostedtoolcache/Python/3.10.18/x64/lib/python3.10/site-packages/urllib3/connectionpool.py", line 534, in _make_request
    response = conn.getresponse()
  File "/opt/hostedtoolcache/Python/3.10.18/x64/lib/python3.10/site-packages/urllib3/connection.py", line 565, in getresponse
    httplib_response = super().getresponse()
  File "/opt/hostedtoolcache/Python/3.10.18/x64/lib/python3.10/http/client.py", line 1375, in getresponse
    response.begin()
  File "/opt/hostedtoolcache/Python/3.10.18/x64/lib/python3.10/http/client.py", line 318, in begin
    version, status, reason = self._read_status()
  File "/opt/hostedtoolcache/Python/3.10.18/x64/lib/python3.10/http/client.py", line 279, in _read_status
    line = str(self.fp.readline(_MAXLINE + 1), "iso-8859-1")
  File "/opt/hostedtoolcache/Python/3.10.18/x64/lib/python3.10/socket.py", line 717, in readinto
    return self._sock.recv_into(b)
TimeoutError: timed out

The above exception was the direct cause of the following exception:

Traceback (most recent call last):
  File "/home/runner/work/Applier-Workflow/Applier-Workflow/scripts/src/stealth_apply.py", line 145, in easy_apply
    driver.get(job_link)
  File "/opt/hostedtoolcache/Python/3.10.18/x64/lib/python3.10/site-packages/undetected_chromedriver/__init__.py", line 496, in get_wrapped
    if self.execute_script("return navigator.webdriver"):
  File "/opt/hostedtoolcache/Python/3.10.18/x64/lib/python3.10/site-packages/selenium/webdriver/remote/webdriver.py", line 551, in execute_script
    return self.execute(command, {"script": script, "args": converted_args})["value"]
  File "/opt/hostedtoolcache/Python/3.10.18/x64/lib/python3.10/site-packages/selenium/webdriver/remote/webdriver.py", line 451, in execute
    response = cast(RemoteConnection, self.command_executor).execute(driver_command, params)
  File "/opt/hostedtoolcache/Python/3.10.18/x64/lib/python3.10/site-packages/selenium/webdriver/remote/remote_connection.py", line 404, in execute
    return self._request(command_info[0], url, body=data)
  File "/opt/hostedtoolcache/Python/3.10.18/x64/lib/python3.10/site-packages/selenium/webdriver/remote/remote_connection.py", line 428, in _request
    response = self._conn.request(method, url, body=body, headers=headers, timeout=self._client_config.timeout)
  File "/opt/hostedtoolcache/Python/3.10.18/x64/lib/python3.10/site-packages/urllib3/_request_methods.py", line 143, in request
    return self.request_encode_body(
  File "/opt/hostedtoolcache/Python/3.10.18/x64/lib/python3.10/site-packages/urllib3/_request_methods.py", line 278, in request_encode_body
    return self.urlopen(method, url, **extra_kw)
  File "/opt/hostedtoolcache/Python/3.10.18/x64/lib/python3.10/site-packages/urllib3/poolmanager.py", line 459, in urlopen
    response = conn.urlopen(method, u.request_uri, **kw)
  File "/opt/hostedtoolcache/Python/3.10.18/x64/lib/python3.10/site-packages/urllib3/connectionpool.py", line 841, in urlopen
    retries = retries.increment(
  File "/opt/hostedtoolcache/Python/3.10.18/x64/lib/python3.10/site-packages/urllib3/util/retry.py", line 474, in increment
    raise reraise(type(error), error, _stacktrace)
  File "/opt/hostedtoolcache/Python/3.10.18/x64/lib/python3.10/site-packages/urllib3/util/util.py", line 39, in reraise
    raise value
  File "/opt/hostedtoolcache/Python/3.10.18/x64/lib/python3.10/site-packages/urllib3/connectionpool.py", line 787, in urlopen
    response = self._make_request(
  File "/opt/hostedtoolcache/Python/3.10.18/x64/lib/python3.10/site-packages/urllib3/connectionpool.py", line 536, in _make_request
    self._raise_timeout(err=e, url=url, timeout_value=read_timeout)
  File "/opt/hostedtoolcache/Python/3.10.18/x64/lib/python3.10/site-packages/urllib3/connectionpool.py", line 367, in _raise_timeout
    raise ReadTimeoutError(
urllib3.exceptions.ReadTimeoutError: HTTPConnectionPool(host='localhost', port=59875): Read timed out. (read timeout=120)
2025-07-17 14:15:07,249 - INFO - üéØ [9/10] Applying to: AI/ML Architect - LINK: https://www.dice.com/job-detail/f631e743-6ee8-4a7d-930c-56435da2ea87
2025-07-17 14:17:18,836 - ERROR -    ‚ùå Cannot click first NEXT button: HTTPConnectionPool(host='localhost', port=59875): Read timed out. (read timeout=120)
2025-07-17 14:19:26,794 - INFO - üéØ [10/10] Applying to: Data Scientist with GenAI & Palantir Experience (Insurance Domain)/ NY/NJ (Onsite) - LINK: https://www.dice.com/job-detail/22487f8f-81db-4985-94ad-e97f77e50529
2025-07-17 14:20:33,592 - ERROR -    ‚ùå Cannot click apply button: Message: element not interactable
  (Session info: chrome=138.0.7204.100); For documentation on this error, please visit: https://www.selenium.dev/documentation/webdriver/troubleshooting/errors#elementnotinteractableexception
Stacktrace:
#0 0x558f539727da <unknown>
#1 0x558f53417133 <unknown>
#2 0x558f5346a00e <unknown>
#3 0x558f5345d0ea <unknown>
#4 0x558f5348e8b2 <unknown>
#5 0x558f5345ca6a <unknown>
#6 0x558f5348ea7e <unknown>
#7 0x558f534b471c <unknown>
#8 0x558f5348e683 <unknown>
#9 0x558f5345ab5b <unknown>
#10 0x558f5345bf31 <unknown>
#11 0x558f5393772b <unknown>
#12 0x558f5393b534 <unknown>
#13 0x558f5391e229 <unknown>
#14 0x558f5393c0d8 <unknown>
#15 0x558f5390261f <unknown>
#16 0x558f5395fdd8 <unknown>
#17 0x558f5395ffb6 <unknown>
#18 0x558f53971af6 <unknown>
#19 0x7fc075a9caa4 <unknown>
#20 0x7fc075b29c3c <unknown>

2025-07-17 14:20:36,235 - INFO - üìä Processing results...
2025-07-17 14:20:36,247 - INFO - üéâ Application run completed!
2025-07-17 14:20:36,247 - INFO -    ‚úÖ Newly applied: 2
2025-07-17 14:20:36,247 - INFO -    ‚è≠Ô∏è  Already applied: 0
2025-07-17 14:20:36,247 - INFO -    ‚ùå Failed: 8
2025-07-17 14:20:36,247 - INFO -    üìä Total processed: 10
2025-07-17 14:20:36,247 - INFO -    üìÅ Total jobs in CSV: 635
2025-07-17 14:20:36,247 - INFO -    üíæ Updated: output/final_ml_jobs.csv
2025-07-17 14:20:36,248 - INFO - üîß Closing browser...
