2025-06-08 21:18:39,581 - INFO - 🚀 Starting stealth job application bot
2025-06-08 21:18:40,237 - INFO - 📂 Loading jobs from output/final_ml_jobs.csv
2025-06-08 21:18:40,248 - INFO -    📊 Total jobs in file: 716
2025-06-08 21:18:40,249 - INFO -    🎯 Easy Apply jobs: 716
2025-06-08 21:18:40,251 - INFO -    ⏳ Jobs to process: 180 (status: pending)
2025-06-08 21:18:40,251 - INFO - 🎲 Will attempt 84 applications this run (target: 84)
2025-06-08 21:18:40,251 - INFO - 🔑 Logging into Dice...
2025-06-08 21:18:42,232 - INFO - ✅ Login successful
2025-06-08 21:18:45,320 - INFO - 🔄 Starting job applications...
2025-06-08 21:18:45,321 - INFO - 🎯 [1/84] Applying to: Lead React Developer with Gen AI
2025-06-08 21:19:01,346 - INFO -    ✅ Successfully applied!
2025-06-08 21:19:10,457 - INFO - 🎯 [2/84] Applying to: Data Scientist
2025-06-08 21:19:26,887 - INFO -    ✅ Successfully applied!
2025-06-08 21:19:36,615 - INFO - 🎯 [3/84] Applying to: AI Solutions Lead- Hybrid role at Montvale, NJ
2025-06-08 21:19:52,559 - INFO -    ✅ Successfully applied!
2025-06-08 21:20:05,621 - INFO - 🎯 [4/84] Applying to: Cloud Infrastructure/AI/ML Engineer
2025-06-08 21:20:23,162 - INFO -    ✅ Successfully applied!
2025-06-08 21:20:33,142 - INFO - 🎯 [5/84] Applying to: GenAI Intern
2025-06-08 21:20:50,131 - INFO -    ✅ Successfully applied!
2025-06-08 21:20:57,438 - INFO - 🎯 [6/84] Applying to: AI/ML Consultant- W2- Hybrid - 322160 - FORD Motors
2025-06-08 21:21:12,592 - INFO -    ✅ Successfully applied!
2025-06-08 21:21:23,225 - INFO - 🎯 [7/84] Applying to: Gen AI Cloud Engineer
2025-06-08 21:21:41,002 - INFO -    ✅ Successfully applied!
2025-06-08 21:21:47,541 - INFO - 🎯 [8/84] Applying to: Python Developer(LLM/Gen AI/ML)
2025-06-08 21:22:02,652 - INFO -    ✅ Successfully applied!
2025-06-08 21:22:12,317 - INFO - 🎯 [9/84] Applying to: Generative AI Engineer
2025-06-08 21:22:25,579 - INFO -    ✅ Successfully applied!
2025-06-08 21:22:35,166 - INFO - 🎯 [10/84] Applying to: Machine Learning Engineer
2025-06-08 21:22:50,542 - INFO -    ✅ Successfully applied!
2025-06-08 21:22:59,754 - INFO - 🎯 [11/84] Applying to: UiPath AI Architect
2025-06-08 21:23:15,318 - INFO -    ✅ Successfully applied!
2025-06-08 21:23:24,467 - INFO - 🎯 [12/84] Applying to: AI/ML & Gen AI Senior Engineer-Hybrid
2025-06-08 21:23:38,665 - INFO -    ✅ Successfully applied!
2025-06-08 21:23:47,999 - INFO - 🎯 [13/84] Applying to: Senior Developer (LLM Implementation Focus)
2025-06-08 21:24:02,224 - INFO -    ✅ Successfully applied!
2025-06-08 21:24:10,122 - INFO - 🎯 [14/84] Applying to: AI/ ML Engineer
2025-06-08 21:24:27,355 - INFO -    ✅ Successfully applied!
2025-06-08 21:24:37,158 - INFO - 🎯 [15/84] Applying to: AI Engineer/ Developer / Michigan (Hybrid)
2025-06-08 21:24:49,659 - INFO -    ✅ Successfully applied!
2025-06-08 21:24:58,420 - INFO - 🎯 [16/84] Applying to: Data Scientist ( Multiple Positions)
2025-06-08 21:25:13,528 - INFO -    ✅ Successfully applied!
2025-06-08 21:25:21,883 - INFO - 🎯 [17/84] Applying to: Gen AI Engineer - Data Scientist
2025-06-08 21:25:35,425 - INFO -    ✅ Successfully applied!
2025-06-08 21:25:48,510 - INFO - 🎯 [18/84] Applying to: AI Engineer-Associate
2025-06-08 21:26:04,962 - INFO -    ✅ Successfully applied!
2025-06-08 21:26:13,887 - INFO - 🎯 [19/84] Applying to: Lead AI/ML Engineer in Seattle, WA | Onsite | Hybrid
2025-06-08 21:26:28,318 - INFO -    ✅ Successfully applied!
2025-06-08 21:26:37,645 - INFO - 🎯 [20/84] Applying to: AI Engineer
2025-06-08 21:26:54,109 - INFO -    ✅ Successfully applied!
2025-06-08 21:27:02,756 - INFO - 🎯 [21/84] Applying to: Senior python developer with AI/ML Exp
2025-06-08 21:27:19,469 - INFO -    ✅ Successfully applied!
2025-06-08 21:27:30,781 - INFO - 🎯 [22/84] Applying to: Senior Data Engineer/Adtech Experience
2025-06-08 21:27:45,685 - INFO -    ✅ Successfully applied!
2025-06-08 21:27:54,870 - INFO - 🎯 [23/84] Applying to: Senior Node.js Developer with Gen AI and LLM
2025-06-08 21:28:08,969 - INFO -    ✅ Successfully applied!
2025-06-08 21:28:18,805 - INFO - 🎯 [24/84] Applying to: Senior Data Engineer
2025-06-08 21:28:34,526 - INFO -    ✅ Successfully applied!
2025-06-08 21:28:44,952 - INFO - 🎯 [25/84] Applying to: Lead Data Scientist
2025-06-08 21:28:59,948 - INFO -    ✅ Successfully applied!
2025-06-08 21:29:07,892 - INFO - 🎯 [26/84] Applying to: Sr Data Scientist :: Charlotte, NC :: C2H role
2025-06-08 21:29:26,392 - INFO -    ✅ Successfully applied!
2025-06-08 21:29:32,926 - INFO - 🎯 [27/84] Applying to: AI/ML Engineering Senior Consultant at Deerfield, IL (Hybrid)
2025-06-08 21:29:50,608 - INFO -    ✅ Successfully applied!
2025-06-08 21:30:00,608 - INFO - 🎯 [28/84] Applying to: Java AI Engineer
2025-06-08 21:30:16,023 - INFO -    ✅ Successfully applied!
2025-06-08 21:30:27,411 - INFO - 🎯 [29/84] Applying to: Data Scientist / Machine Learning Engineer/LLM
2025-06-08 21:30:44,225 - INFO -    ✅ Successfully applied!
2025-06-08 21:30:54,712 - INFO - 🎯 [30/84] Applying to: Project Manager Must have AI/ML and Gen AI
2025-06-08 21:31:10,564 - INFO -    ✅ Successfully applied!
2025-06-08 21:31:22,609 - INFO - 🎯 [31/84] Applying to: Data Scientist
2025-06-08 21:31:37,850 - INFO -    ✅ Successfully applied!
2025-06-08 21:31:45,416 - INFO - 🎯 [32/84] Applying to: AI Architect
2025-06-08 21:31:58,927 - INFO -    ✅ Successfully applied!
2025-06-08 21:32:08,377 - INFO - 🎯 [33/84] Applying to: Need AI/ML Engineer in Arlington, Texas (Day 1 Onsite) for Fulltime
2025-06-08 21:32:24,686 - INFO -    ✅ Successfully applied!
2025-06-08 21:32:36,848 - INFO - 🎯 [34/84] Applying to: Perception Machine Learning Engineer
2025-06-08 21:32:55,518 - INFO -    ✅ Successfully applied!
2025-06-08 21:33:05,860 - INFO - 🎯 [35/84] Applying to: Machine Learning Developer II
2025-06-08 21:33:19,799 - INFO -    ✅ Successfully applied!
2025-06-08 21:33:26,057 - INFO - 🎯 [36/84] Applying to: AI/ML Architect in Reston, VA
2025-06-08 21:33:40,621 - INFO -    ✅ Successfully applied!
2025-06-08 21:33:51,143 - INFO - 🎯 [37/84] Applying to: AI/ML & Gen AI Senior Engineer
2025-06-08 21:34:07,173 - INFO -    ✅ Successfully applied!
2025-06-08 21:34:17,868 - INFO - 🎯 [38/84] Applying to: AL/ML Senior Engineer
2025-06-08 21:34:31,710 - ERROR -    ❌ Cannot click first NEXT button: Message: invalid session id: session deleted as the browser has closed the connection
from disconnected: Unable to receive message from renderer
  (Session info: chrome=136.0.7103.94)
Stacktrace:
#0 0x56545a35b71a <unknown>
#1 0x565459dfe0a0 <unknown>
#2 0x565459de5ea0 <unknown>
#3 0x565459de5ba2 <unknown>
#4 0x565459de39ef <unknown>
#5 0x565459de431f <unknown>
#6 0x565459e02935 <unknown>
#7 0x565459e032a8 <unknown>
#8 0x565459e07578 <unknown>
#9 0x565459e07603 <unknown>
#10 0x565459e4f3e5 <unknown>
#11 0x565459e4fba1 <unknown>
#12 0x565459e9dea4 <unknown>
#13 0x565459e753cd <unknown>
#14 0x565459e9b2a0 <unknown>
#15 0x565459e75173 <unknown>
#16 0x565459e41d4b <unknown>
#17 0x565459e429b1 <unknown>
#18 0x56545a3208cb <unknown>
#19 0x56545a3247ca <unknown>
#20 0x56545a308622 <unknown>
#21 0x56545a325354 <unknown>
#22 0x56545a2ed45f <unknown>
#23 0x56545a3494f8 <unknown>
#24 0x56545a3496d6 <unknown>
#25 0x56545a35a586 <unknown>
#26 0x7f8bd689caa4 <unknown>
#27 0x7f8bd6929c3c <unknown>

2025-06-08 21:34:39,229 - INFO - 🎯 [39/84] Applying to: AI/ML Engineer
2025-06-08 21:34:39,236 - ERROR -    ❌ Application failed: Message: invalid session id
Stacktrace:
#0 0x56545a35b71a <unknown>
#1 0x565459dfdef3 <unknown>
#2 0x565459e40f0f <unknown>
#3 0x565459e752a6 <unknown>
#4 0x565459e6fbe7 <unknown>
#5 0x565459e6ed25 <unknown>
#6 0x565459dc7a88 <unknown>
#7 0x56545a3208cb <unknown>
#8 0x56545a3247ca <unknown>
#9 0x56545a308622 <unknown>
#10 0x56545a325354 <unknown>
#11 0x56545a2ed45f <unknown>
#12 0x565459dc5821 <unknown>
#13 0x7f8bd682a1ca <unknown>
#14 0x7f8bd682a28b __libc_start_main
#15 0x565459d8d4ea _start

2025-06-08 21:34:39,236 - ERROR - Full error for AI/ML Engineer:
Traceback (most recent call last):
  File "/home/runner/work/Applier-Workflow/Applier-Workflow/scripts/src/stealth_apply.py", line 149, in easy_apply
    driver.get(job_link)
  File "/opt/hostedtoolcache/Python/3.10.17/x64/lib/python3.10/site-packages/undetected_chromedriver/__init__.py", line 496, in get_wrapped
    if self.execute_script("return navigator.webdriver"):
  File "/opt/hostedtoolcache/Python/3.10.17/x64/lib/python3.10/site-packages/selenium/webdriver/remote/webdriver.py", line 544, in execute_script
    return self.execute(command, {"script": script, "args": converted_args})["value"]
  File "/opt/hostedtoolcache/Python/3.10.17/x64/lib/python3.10/site-packages/selenium/webdriver/remote/webdriver.py", line 447, in execute
    self.error_handler.check_response(response)
  File "/opt/hostedtoolcache/Python/3.10.17/x64/lib/python3.10/site-packages/selenium/webdriver/remote/errorhandler.py", line 232, in check_response
    raise exception_class(message, screen, stacktrace)
selenium.common.exceptions.InvalidSessionIdException: Message: invalid session id
Stacktrace:
#0 0x56545a35b71a <unknown>
#1 0x565459dfdef3 <unknown>
#2 0x565459e40f0f <unknown>
#3 0x565459e752a6 <unknown>
#4 0x565459e6fbe7 <unknown>
#5 0x565459e6ed25 <unknown>
#6 0x565459dc7a88 <unknown>
#7 0x56545a3208cb <unknown>
#8 0x56545a3247ca <unknown>
#9 0x56545a308622 <unknown>
#10 0x56545a325354 <unknown>
#11 0x56545a2ed45f <unknown>
#12 0x565459dc5821 <unknown>
#13 0x7f8bd682a1ca <unknown>
#14 0x7f8bd682a28b __libc_start_main
#15 0x565459d8d4ea _start

2025-06-08 21:34:50,642 - INFO - 🎯 [40/84] Applying to: AWS AI Data Engineer
2025-06-08 21:34:50,649 - ERROR -    ❌ Application failed: Message: invalid session id
Stacktrace:
#0 0x56545a35b71a <unknown>
#1 0x565459dfdef3 <unknown>
#2 0x565459e40f0f <unknown>
#3 0x565459e752a6 <unknown>
#4 0x565459e6fbe7 <unknown>
#5 0x565459e6ed25 <unknown>
#6 0x565459dc7a88 <unknown>
#7 0x56545a3208cb <unknown>
#8 0x56545a3247ca <unknown>
#9 0x56545a308622 <unknown>
#10 0x56545a325354 <unknown>
#11 0x56545a2ed45f <unknown>
#12 0x565459dc5821 <unknown>
#13 0x7f8bd682a1ca <unknown>
#14 0x7f8bd682a28b __libc_start_main
#15 0x565459d8d4ea _start

2025-06-08 21:34:50,649 - ERROR - Full error for AWS AI Data Engineer:
Traceback (most recent call last):
  File "/home/runner/work/Applier-Workflow/Applier-Workflow/scripts/src/stealth_apply.py", line 149, in easy_apply
    driver.get(job_link)
  File "/opt/hostedtoolcache/Python/3.10.17/x64/lib/python3.10/site-packages/undetected_chromedriver/__init__.py", line 496, in get_wrapped
    if self.execute_script("return navigator.webdriver"):
  File "/opt/hostedtoolcache/Python/3.10.17/x64/lib/python3.10/site-packages/selenium/webdriver/remote/webdriver.py", line 544, in execute_script
    return self.execute(command, {"script": script, "args": converted_args})["value"]
  File "/opt/hostedtoolcache/Python/3.10.17/x64/lib/python3.10/site-packages/selenium/webdriver/remote/webdriver.py", line 447, in execute
    self.error_handler.check_response(response)
  File "/opt/hostedtoolcache/Python/3.10.17/x64/lib/python3.10/site-packages/selenium/webdriver/remote/errorhandler.py", line 232, in check_response
    raise exception_class(message, screen, stacktrace)
selenium.common.exceptions.InvalidSessionIdException: Message: invalid session id
Stacktrace:
#0 0x56545a35b71a <unknown>
#1 0x565459dfdef3 <unknown>
#2 0x565459e40f0f <unknown>
#3 0x565459e752a6 <unknown>
#4 0x565459e6fbe7 <unknown>
#5 0x565459e6ed25 <unknown>
#6 0x565459dc7a88 <unknown>
#7 0x56545a3208cb <unknown>
#8 0x56545a3247ca <unknown>
#9 0x56545a308622 <unknown>
#10 0x56545a325354 <unknown>
#11 0x56545a2ed45f <unknown>
#12 0x565459dc5821 <unknown>
#13 0x7f8bd682a1ca <unknown>
#14 0x7f8bd682a28b __libc_start_main
#15 0x565459d8d4ea _start

2025-06-08 21:35:00,021 - INFO - 🎯 [41/84] Applying to: Data Scientist:::::::::Onsite
2025-06-08 21:35:00,028 - ERROR -    ❌ Application failed: Message: invalid session id
Stacktrace:
#0 0x56545a35b71a <unknown>
#1 0x565459dfdef3 <unknown>
#2 0x565459e40f0f <unknown>
#3 0x565459e752a6 <unknown>
#4 0x565459e6fbe7 <unknown>
#5 0x565459e6ed25 <unknown>
#6 0x565459dc7a88 <unknown>
#7 0x56545a3208cb <unknown>
#8 0x56545a3247ca <unknown>
#9 0x56545a308622 <unknown>
#10 0x56545a325354 <unknown>
#11 0x56545a2ed45f <unknown>
#12 0x565459dc5821 <unknown>
#13 0x7f8bd682a1ca <unknown>
#14 0x7f8bd682a28b __libc_start_main
#15 0x565459d8d4ea _start

2025-06-08 21:35:00,028 - ERROR - Full error for Data Scientist:::::::::Onsite:
Traceback (most recent call last):
  File "/home/runner/work/Applier-Workflow/Applier-Workflow/scripts/src/stealth_apply.py", line 149, in easy_apply
    driver.get(job_link)
  File "/opt/hostedtoolcache/Python/3.10.17/x64/lib/python3.10/site-packages/undetected_chromedriver/__init__.py", line 496, in get_wrapped
    if self.execute_script("return navigator.webdriver"):
  File "/opt/hostedtoolcache/Python/3.10.17/x64/lib/python3.10/site-packages/selenium/webdriver/remote/webdriver.py", line 544, in execute_script
    return self.execute(command, {"script": script, "args": converted_args})["value"]
  File "/opt/hostedtoolcache/Python/3.10.17/x64/lib/python3.10/site-packages/selenium/webdriver/remote/webdriver.py", line 447, in execute
    self.error_handler.check_response(response)
  File "/opt/hostedtoolcache/Python/3.10.17/x64/lib/python3.10/site-packages/selenium/webdriver/remote/errorhandler.py", line 232, in check_response
    raise exception_class(message, screen, stacktrace)
selenium.common.exceptions.InvalidSessionIdException: Message: invalid session id
Stacktrace:
#0 0x56545a35b71a <unknown>
#1 0x565459dfdef3 <unknown>
#2 0x565459e40f0f <unknown>
#3 0x565459e752a6 <unknown>
#4 0x565459e6fbe7 <unknown>
#5 0x565459e6ed25 <unknown>
#6 0x565459dc7a88 <unknown>
#7 0x56545a3208cb <unknown>
#8 0x56545a3247ca <unknown>
#9 0x56545a308622 <unknown>
#10 0x56545a325354 <unknown>
#11 0x56545a2ed45f <unknown>
#12 0x565459dc5821 <unknown>
#13 0x7f8bd682a1ca <unknown>
#14 0x7f8bd682a28b __libc_start_main
#15 0x565459d8d4ea _start

2025-06-08 21:35:07,441 - INFO - 🎯 [42/84] Applying to: Senior Director - AI/ML Engineering
2025-06-08 21:35:07,448 - ERROR -    ❌ Application failed: Message: invalid session id
Stacktrace:
#0 0x56545a35b71a <unknown>
#1 0x565459dfdef3 <unknown>
#2 0x565459e40f0f <unknown>
#3 0x565459e752a6 <unknown>
#4 0x565459e6fbe7 <unknown>
#5 0x565459e6ed25 <unknown>
#6 0x565459dc7a88 <unknown>
#7 0x56545a3208cb <unknown>
#8 0x56545a3247ca <unknown>
#9 0x56545a308622 <unknown>
#10 0x56545a325354 <unknown>
#11 0x56545a2ed45f <unknown>
#12 0x565459dc5821 <unknown>
#13 0x7f8bd682a1ca <unknown>
#14 0x7f8bd682a28b __libc_start_main
#15 0x565459d8d4ea _start

2025-06-08 21:35:07,448 - ERROR - Full error for Senior Director - AI/ML Engineering:
Traceback (most recent call last):
  File "/home/runner/work/Applier-Workflow/Applier-Workflow/scripts/src/stealth_apply.py", line 149, in easy_apply
    driver.get(job_link)
  File "/opt/hostedtoolcache/Python/3.10.17/x64/lib/python3.10/site-packages/undetected_chromedriver/__init__.py", line 496, in get_wrapped
    if self.execute_script("return navigator.webdriver"):
  File "/opt/hostedtoolcache/Python/3.10.17/x64/lib/python3.10/site-packages/selenium/webdriver/remote/webdriver.py", line 544, in execute_script
    return self.execute(command, {"script": script, "args": converted_args})["value"]
  File "/opt/hostedtoolcache/Python/3.10.17/x64/lib/python3.10/site-packages/selenium/webdriver/remote/webdriver.py", line 447, in execute
    self.error_handler.check_response(response)
  File "/opt/hostedtoolcache/Python/3.10.17/x64/lib/python3.10/site-packages/selenium/webdriver/remote/errorhandler.py", line 232, in check_response
    raise exception_class(message, screen, stacktrace)
selenium.common.exceptions.InvalidSessionIdException: Message: invalid session id
Stacktrace:
#0 0x56545a35b71a <unknown>
#1 0x565459dfdef3 <unknown>
#2 0x565459e40f0f <unknown>
#3 0x565459e752a6 <unknown>
#4 0x565459e6fbe7 <unknown>
#5 0x565459e6ed25 <unknown>
#6 0x565459dc7a88 <unknown>
#7 0x56545a3208cb <unknown>
#8 0x56545a3247ca <unknown>
#9 0x56545a308622 <unknown>
#10 0x56545a325354 <unknown>
#11 0x56545a2ed45f <unknown>
#12 0x565459dc5821 <unknown>
#13 0x7f8bd682a1ca <unknown>
#14 0x7f8bd682a28b __libc_start_main
#15 0x565459d8d4ea _start

2025-06-08 21:35:15,974 - INFO - 🎯 [43/84] Applying to: AI Research Scientist/Engineer
2025-06-08 21:35:15,981 - ERROR -    ❌ Application failed: Message: invalid session id
Stacktrace:
#0 0x56545a35b71a <unknown>
#1 0x565459dfdef3 <unknown>
#2 0x565459e40f0f <unknown>
#3 0x565459e752a6 <unknown>
#4 0x565459e6fbe7 <unknown>
#5 0x565459e6ed25 <unknown>
#6 0x565459dc7a88 <unknown>
#7 0x56545a3208cb <unknown>
#8 0x56545a3247ca <unknown>
#9 0x56545a308622 <unknown>
#10 0x56545a325354 <unknown>
#11 0x56545a2ed45f <unknown>
#12 0x565459dc5821 <unknown>
#13 0x7f8bd682a1ca <unknown>
#14 0x7f8bd682a28b __libc_start_main
#15 0x565459d8d4ea _start

2025-06-08 21:35:15,981 - ERROR - Full error for AI Research Scientist/Engineer:
Traceback (most recent call last):
  File "/home/runner/work/Applier-Workflow/Applier-Workflow/scripts/src/stealth_apply.py", line 149, in easy_apply
    driver.get(job_link)
  File "/opt/hostedtoolcache/Python/3.10.17/x64/lib/python3.10/site-packages/undetected_chromedriver/__init__.py", line 496, in get_wrapped
    if self.execute_script("return navigator.webdriver"):
  File "/opt/hostedtoolcache/Python/3.10.17/x64/lib/python3.10/site-packages/selenium/webdriver/remote/webdriver.py", line 544, in execute_script
    return self.execute(command, {"script": script, "args": converted_args})["value"]
  File "/opt/hostedtoolcache/Python/3.10.17/x64/lib/python3.10/site-packages/selenium/webdriver/remote/webdriver.py", line 447, in execute
    self.error_handler.check_response(response)
  File "/opt/hostedtoolcache/Python/3.10.17/x64/lib/python3.10/site-packages/selenium/webdriver/remote/errorhandler.py", line 232, in check_response
    raise exception_class(message, screen, stacktrace)
selenium.common.exceptions.InvalidSessionIdException: Message: invalid session id
Stacktrace:
#0 0x56545a35b71a <unknown>
#1 0x565459dfdef3 <unknown>
#2 0x565459e40f0f <unknown>
#3 0x565459e752a6 <unknown>
#4 0x565459e6fbe7 <unknown>
#5 0x565459e6ed25 <unknown>
#6 0x565459dc7a88 <unknown>
#7 0x56545a3208cb <unknown>
#8 0x56545a3247ca <unknown>
#9 0x56545a308622 <unknown>
#10 0x56545a325354 <unknown>
#11 0x56545a2ed45f <unknown>
#12 0x565459dc5821 <unknown>
#13 0x7f8bd682a1ca <unknown>
#14 0x7f8bd682a28b __libc_start_main
#15 0x565459d8d4ea _start

2025-06-08 21:35:23,612 - INFO - 🎯 [44/84] Applying to: Senior Level Data Engineer / Healthcare / Python / Django / PostgreSQL
2025-06-08 21:35:23,620 - ERROR -    ❌ Application failed: Message: invalid session id
Stacktrace:
#0 0x56545a35b71a <unknown>
#1 0x565459dfdef3 <unknown>
#2 0x565459e40f0f <unknown>
#3 0x565459e752a6 <unknown>
#4 0x565459e6fbe7 <unknown>
#5 0x565459e6ed25 <unknown>
#6 0x565459dc7a88 <unknown>
#7 0x56545a3208cb <unknown>
#8 0x56545a3247ca <unknown>
#9 0x56545a308622 <unknown>
#10 0x56545a325354 <unknown>
#11 0x56545a2ed45f <unknown>
#12 0x565459dc5821 <unknown>
#13 0x7f8bd682a1ca <unknown>
#14 0x7f8bd682a28b __libc_start_main
#15 0x565459d8d4ea _start

2025-06-08 21:35:23,620 - ERROR - Full error for Senior Level Data Engineer / Healthcare / Python / Django / PostgreSQL:
Traceback (most recent call last):
  File "/home/runner/work/Applier-Workflow/Applier-Workflow/scripts/src/stealth_apply.py", line 149, in easy_apply
    driver.get(job_link)
  File "/opt/hostedtoolcache/Python/3.10.17/x64/lib/python3.10/site-packages/undetected_chromedriver/__init__.py", line 496, in get_wrapped
    if self.execute_script("return navigator.webdriver"):
  File "/opt/hostedtoolcache/Python/3.10.17/x64/lib/python3.10/site-packages/selenium/webdriver/remote/webdriver.py", line 544, in execute_script
    return self.execute(command, {"script": script, "args": converted_args})["value"]
  File "/opt/hostedtoolcache/Python/3.10.17/x64/lib/python3.10/site-packages/selenium/webdriver/remote/webdriver.py", line 447, in execute
    self.error_handler.check_response(response)
  File "/opt/hostedtoolcache/Python/3.10.17/x64/lib/python3.10/site-packages/selenium/webdriver/remote/errorhandler.py", line 232, in check_response
    raise exception_class(message, screen, stacktrace)
selenium.common.exceptions.InvalidSessionIdException: Message: invalid session id
Stacktrace:
#0 0x56545a35b71a <unknown>
#1 0x565459dfdef3 <unknown>
#2 0x565459e40f0f <unknown>
#3 0x565459e752a6 <unknown>
#4 0x565459e6fbe7 <unknown>
#5 0x565459e6ed25 <unknown>
#6 0x565459dc7a88 <unknown>
#7 0x56545a3208cb <unknown>
#8 0x56545a3247ca <unknown>
#9 0x56545a308622 <unknown>
#10 0x56545a325354 <unknown>
#11 0x56545a2ed45f <unknown>
#12 0x565459dc5821 <unknown>
#13 0x7f8bd682a1ca <unknown>
#14 0x7f8bd682a28b __libc_start_main
#15 0x565459d8d4ea _start

2025-06-08 21:35:31,918 - INFO - 🎯 [45/84] Applying to: Machine Learning Engineer, Specialist
2025-06-08 21:35:31,926 - ERROR -    ❌ Application failed: Message: invalid session id
Stacktrace:
#0 0x56545a35b71a <unknown>
#1 0x565459dfdef3 <unknown>
#2 0x565459e40f0f <unknown>
#3 0x565459e752a6 <unknown>
#4 0x565459e6fbe7 <unknown>
#5 0x565459e6ed25 <unknown>
#6 0x565459dc7a88 <unknown>
#7 0x56545a3208cb <unknown>
#8 0x56545a3247ca <unknown>
#9 0x56545a308622 <unknown>
#10 0x56545a325354 <unknown>
#11 0x56545a2ed45f <unknown>
#12 0x565459dc5821 <unknown>
#13 0x7f8bd682a1ca <unknown>
#14 0x7f8bd682a28b __libc_start_main
#15 0x565459d8d4ea _start

2025-06-08 21:35:31,926 - ERROR - Full error for Machine Learning Engineer, Specialist:
Traceback (most recent call last):
  File "/home/runner/work/Applier-Workflow/Applier-Workflow/scripts/src/stealth_apply.py", line 149, in easy_apply
    driver.get(job_link)
  File "/opt/hostedtoolcache/Python/3.10.17/x64/lib/python3.10/site-packages/undetected_chromedriver/__init__.py", line 496, in get_wrapped
    if self.execute_script("return navigator.webdriver"):
  File "/opt/hostedtoolcache/Python/3.10.17/x64/lib/python3.10/site-packages/selenium/webdriver/remote/webdriver.py", line 544, in execute_script
    return self.execute(command, {"script": script, "args": converted_args})["value"]
  File "/opt/hostedtoolcache/Python/3.10.17/x64/lib/python3.10/site-packages/selenium/webdriver/remote/webdriver.py", line 447, in execute
    self.error_handler.check_response(response)
  File "/opt/hostedtoolcache/Python/3.10.17/x64/lib/python3.10/site-packages/selenium/webdriver/remote/errorhandler.py", line 232, in check_response
    raise exception_class(message, screen, stacktrace)
selenium.common.exceptions.InvalidSessionIdException: Message: invalid session id
Stacktrace:
#0 0x56545a35b71a <unknown>
#1 0x565459dfdef3 <unknown>
#2 0x565459e40f0f <unknown>
#3 0x565459e752a6 <unknown>
#4 0x565459e6fbe7 <unknown>
#5 0x565459e6ed25 <unknown>
#6 0x565459dc7a88 <unknown>
#7 0x56545a3208cb <unknown>
#8 0x56545a3247ca <unknown>
#9 0x56545a308622 <unknown>
#10 0x56545a325354 <unknown>
#11 0x56545a2ed45f <unknown>
#12 0x565459dc5821 <unknown>
#13 0x7f8bd682a1ca <unknown>
#14 0x7f8bd682a28b __libc_start_main
#15 0x565459d8d4ea _start

2025-06-08 21:35:41,423 - INFO - 🎯 [46/84] Applying to: Data Scientist
2025-06-08 21:35:41,430 - ERROR -    ❌ Application failed: Message: invalid session id
Stacktrace:
#0 0x56545a35b71a <unknown>
#1 0x565459dfdef3 <unknown>
#2 0x565459e40f0f <unknown>
#3 0x565459e752a6 <unknown>
#4 0x565459e6fbe7 <unknown>
#5 0x565459e6ed25 <unknown>
#6 0x565459dc7a88 <unknown>
#7 0x56545a3208cb <unknown>
#8 0x56545a3247ca <unknown>
#9 0x56545a308622 <unknown>
#10 0x56545a325354 <unknown>
#11 0x56545a2ed45f <unknown>
#12 0x565459dc5821 <unknown>
#13 0x7f8bd682a1ca <unknown>
#14 0x7f8bd682a28b __libc_start_main
#15 0x565459d8d4ea _start

2025-06-08 21:35:41,431 - ERROR - Full error for Data Scientist:
Traceback (most recent call last):
  File "/home/runner/work/Applier-Workflow/Applier-Workflow/scripts/src/stealth_apply.py", line 149, in easy_apply
    driver.get(job_link)
  File "/opt/hostedtoolcache/Python/3.10.17/x64/lib/python3.10/site-packages/undetected_chromedriver/__init__.py", line 496, in get_wrapped
    if self.execute_script("return navigator.webdriver"):
  File "/opt/hostedtoolcache/Python/3.10.17/x64/lib/python3.10/site-packages/selenium/webdriver/remote/webdriver.py", line 544, in execute_script
    return self.execute(command, {"script": script, "args": converted_args})["value"]
  File "/opt/hostedtoolcache/Python/3.10.17/x64/lib/python3.10/site-packages/selenium/webdriver/remote/webdriver.py", line 447, in execute
    self.error_handler.check_response(response)
  File "/opt/hostedtoolcache/Python/3.10.17/x64/lib/python3.10/site-packages/selenium/webdriver/remote/errorhandler.py", line 232, in check_response
    raise exception_class(message, screen, stacktrace)
selenium.common.exceptions.InvalidSessionIdException: Message: invalid session id
Stacktrace:
#0 0x56545a35b71a <unknown>
#1 0x565459dfdef3 <unknown>
#2 0x565459e40f0f <unknown>
#3 0x565459e752a6 <unknown>
#4 0x565459e6fbe7 <unknown>
#5 0x565459e6ed25 <unknown>
#6 0x565459dc7a88 <unknown>
#7 0x56545a3208cb <unknown>
#8 0x56545a3247ca <unknown>
#9 0x56545a308622 <unknown>
#10 0x56545a325354 <unknown>
#11 0x56545a2ed45f <unknown>
#12 0x565459dc5821 <unknown>
#13 0x7f8bd682a1ca <unknown>
#14 0x7f8bd682a28b __libc_start_main
#15 0x565459d8d4ea _start

2025-06-08 21:35:52,360 - INFO - 🎯 [47/84] Applying to: GenAI Data Scientist::Reston, VA
2025-06-08 21:35:52,367 - ERROR -    ❌ Application failed: Message: invalid session id
Stacktrace:
#0 0x56545a35b71a <unknown>
#1 0x565459dfdef3 <unknown>
#2 0x565459e40f0f <unknown>
#3 0x565459e752a6 <unknown>
#4 0x565459e6fbe7 <unknown>
#5 0x565459e6ed25 <unknown>
#6 0x565459dc7a88 <unknown>
#7 0x56545a3208cb <unknown>
#8 0x56545a3247ca <unknown>
#9 0x56545a308622 <unknown>
#10 0x56545a325354 <unknown>
#11 0x56545a2ed45f <unknown>
#12 0x565459dc5821 <unknown>
#13 0x7f8bd682a1ca <unknown>
#14 0x7f8bd682a28b __libc_start_main
#15 0x565459d8d4ea _start

2025-06-08 21:35:52,367 - ERROR - Full error for GenAI Data Scientist::Reston, VA:
Traceback (most recent call last):
  File "/home/runner/work/Applier-Workflow/Applier-Workflow/scripts/src/stealth_apply.py", line 149, in easy_apply
    driver.get(job_link)
  File "/opt/hostedtoolcache/Python/3.10.17/x64/lib/python3.10/site-packages/undetected_chromedriver/__init__.py", line 496, in get_wrapped
    if self.execute_script("return navigator.webdriver"):
  File "/opt/hostedtoolcache/Python/3.10.17/x64/lib/python3.10/site-packages/selenium/webdriver/remote/webdriver.py", line 544, in execute_script
    return self.execute(command, {"script": script, "args": converted_args})["value"]
  File "/opt/hostedtoolcache/Python/3.10.17/x64/lib/python3.10/site-packages/selenium/webdriver/remote/webdriver.py", line 447, in execute
    self.error_handler.check_response(response)
  File "/opt/hostedtoolcache/Python/3.10.17/x64/lib/python3.10/site-packages/selenium/webdriver/remote/errorhandler.py", line 232, in check_response
    raise exception_class(message, screen, stacktrace)
selenium.common.exceptions.InvalidSessionIdException: Message: invalid session id
Stacktrace:
#0 0x56545a35b71a <unknown>
#1 0x565459dfdef3 <unknown>
#2 0x565459e40f0f <unknown>
#3 0x565459e752a6 <unknown>
#4 0x565459e6fbe7 <unknown>
#5 0x565459e6ed25 <unknown>
#6 0x565459dc7a88 <unknown>
#7 0x56545a3208cb <unknown>
#8 0x56545a3247ca <unknown>
#9 0x56545a308622 <unknown>
#10 0x56545a325354 <unknown>
#11 0x56545a2ed45f <unknown>
#12 0x565459dc5821 <unknown>
#13 0x7f8bd682a1ca <unknown>
#14 0x7f8bd682a28b __libc_start_main
#15 0x565459d8d4ea _start

2025-06-08 21:36:01,040 - INFO - 🎯 [48/84] Applying to: Systems / ML Engineer III
2025-06-08 21:36:01,048 - ERROR -    ❌ Application failed: Message: invalid session id
Stacktrace:
#0 0x56545a35b71a <unknown>
#1 0x565459dfdef3 <unknown>
#2 0x565459e40f0f <unknown>
#3 0x565459e752a6 <unknown>
#4 0x565459e6fbe7 <unknown>
#5 0x565459e6ed25 <unknown>
#6 0x565459dc7a88 <unknown>
#7 0x56545a3208cb <unknown>
#8 0x56545a3247ca <unknown>
#9 0x56545a308622 <unknown>
#10 0x56545a325354 <unknown>
#11 0x56545a2ed45f <unknown>
#12 0x565459dc5821 <unknown>
#13 0x7f8bd682a1ca <unknown>
#14 0x7f8bd682a28b __libc_start_main
#15 0x565459d8d4ea _start

2025-06-08 21:36:01,048 - ERROR - Full error for Systems / ML Engineer III:
Traceback (most recent call last):
  File "/home/runner/work/Applier-Workflow/Applier-Workflow/scripts/src/stealth_apply.py", line 149, in easy_apply
    driver.get(job_link)
  File "/opt/hostedtoolcache/Python/3.10.17/x64/lib/python3.10/site-packages/undetected_chromedriver/__init__.py", line 496, in get_wrapped
    if self.execute_script("return navigator.webdriver"):
  File "/opt/hostedtoolcache/Python/3.10.17/x64/lib/python3.10/site-packages/selenium/webdriver/remote/webdriver.py", line 544, in execute_script
    return self.execute(command, {"script": script, "args": converted_args})["value"]
  File "/opt/hostedtoolcache/Python/3.10.17/x64/lib/python3.10/site-packages/selenium/webdriver/remote/webdriver.py", line 447, in execute
    self.error_handler.check_response(response)
  File "/opt/hostedtoolcache/Python/3.10.17/x64/lib/python3.10/site-packages/selenium/webdriver/remote/errorhandler.py", line 232, in check_response
    raise exception_class(message, screen, stacktrace)
selenium.common.exceptions.InvalidSessionIdException: Message: invalid session id
Stacktrace:
#0 0x56545a35b71a <unknown>
#1 0x565459dfdef3 <unknown>
#2 0x565459e40f0f <unknown>
#3 0x565459e752a6 <unknown>
#4 0x565459e6fbe7 <unknown>
#5 0x565459e6ed25 <unknown>
#6 0x565459dc7a88 <unknown>
#7 0x56545a3208cb <unknown>
#8 0x56545a3247ca <unknown>
#9 0x56545a308622 <unknown>
#10 0x56545a325354 <unknown>
#11 0x56545a2ed45f <unknown>
#12 0x565459dc5821 <unknown>
#13 0x7f8bd682a1ca <unknown>
#14 0x7f8bd682a28b __libc_start_main
#15 0x565459d8d4ea _start

2025-06-08 21:36:06,668 - INFO - 🎯 [49/84] Applying to: LLM Engineer_ Dallas, TX (Need Local)
2025-06-08 21:36:06,676 - ERROR -    ❌ Application failed: Message: invalid session id
Stacktrace:
#0 0x56545a35b71a <unknown>
#1 0x565459dfdef3 <unknown>
#2 0x565459e40f0f <unknown>
#3 0x565459e752a6 <unknown>
#4 0x565459e6fbe7 <unknown>
#5 0x565459e6ed25 <unknown>
#6 0x565459dc7a88 <unknown>
#7 0x56545a3208cb <unknown>
#8 0x56545a3247ca <unknown>
#9 0x56545a308622 <unknown>
#10 0x56545a325354 <unknown>
#11 0x56545a2ed45f <unknown>
#12 0x565459dc5821 <unknown>
#13 0x7f8bd682a1ca <unknown>
#14 0x7f8bd682a28b __libc_start_main
#15 0x565459d8d4ea _start

2025-06-08 21:36:06,676 - ERROR - Full error for LLM Engineer_ Dallas, TX (Need Local):
Traceback (most recent call last):
  File "/home/runner/work/Applier-Workflow/Applier-Workflow/scripts/src/stealth_apply.py", line 149, in easy_apply
    driver.get(job_link)
  File "/opt/hostedtoolcache/Python/3.10.17/x64/lib/python3.10/site-packages/undetected_chromedriver/__init__.py", line 496, in get_wrapped
    if self.execute_script("return navigator.webdriver"):
  File "/opt/hostedtoolcache/Python/3.10.17/x64/lib/python3.10/site-packages/selenium/webdriver/remote/webdriver.py", line 544, in execute_script
    return self.execute(command, {"script": script, "args": converted_args})["value"]
  File "/opt/hostedtoolcache/Python/3.10.17/x64/lib/python3.10/site-packages/selenium/webdriver/remote/webdriver.py", line 447, in execute
    self.error_handler.check_response(response)
  File "/opt/hostedtoolcache/Python/3.10.17/x64/lib/python3.10/site-packages/selenium/webdriver/remote/errorhandler.py", line 232, in check_response
    raise exception_class(message, screen, stacktrace)
selenium.common.exceptions.InvalidSessionIdException: Message: invalid session id
Stacktrace:
#0 0x56545a35b71a <unknown>
#1 0x565459dfdef3 <unknown>
#2 0x565459e40f0f <unknown>
#3 0x565459e752a6 <unknown>
#4 0x565459e6fbe7 <unknown>
#5 0x565459e6ed25 <unknown>
#6 0x565459dc7a88 <unknown>
#7 0x56545a3208cb <unknown>
#8 0x56545a3247ca <unknown>
#9 0x56545a308622 <unknown>
#10 0x56545a325354 <unknown>
#11 0x56545a2ed45f <unknown>
#12 0x565459dc5821 <unknown>
#13 0x7f8bd682a1ca <unknown>
#14 0x7f8bd682a28b __libc_start_main
#15 0x565459d8d4ea _start

2025-06-08 21:36:16,905 - INFO - 🎯 [50/84] Applying to: Data Scientist
2025-06-08 21:36:16,912 - ERROR -    ❌ Application failed: Message: invalid session id
Stacktrace:
#0 0x56545a35b71a <unknown>
#1 0x565459dfdef3 <unknown>
#2 0x565459e40f0f <unknown>
#3 0x565459e752a6 <unknown>
#4 0x565459e6fbe7 <unknown>
#5 0x565459e6ed25 <unknown>
#6 0x565459dc7a88 <unknown>
#7 0x56545a3208cb <unknown>
#8 0x56545a3247ca <unknown>
#9 0x56545a308622 <unknown>
#10 0x56545a325354 <unknown>
#11 0x56545a2ed45f <unknown>
#12 0x565459dc5821 <unknown>
#13 0x7f8bd682a1ca <unknown>
#14 0x7f8bd682a28b __libc_start_main
#15 0x565459d8d4ea _start

2025-06-08 21:36:16,912 - ERROR - Full error for Data Scientist:
Traceback (most recent call last):
  File "/home/runner/work/Applier-Workflow/Applier-Workflow/scripts/src/stealth_apply.py", line 149, in easy_apply
    driver.get(job_link)
  File "/opt/hostedtoolcache/Python/3.10.17/x64/lib/python3.10/site-packages/undetected_chromedriver/__init__.py", line 496, in get_wrapped
    if self.execute_script("return navigator.webdriver"):
  File "/opt/hostedtoolcache/Python/3.10.17/x64/lib/python3.10/site-packages/selenium/webdriver/remote/webdriver.py", line 544, in execute_script
    return self.execute(command, {"script": script, "args": converted_args})["value"]
  File "/opt/hostedtoolcache/Python/3.10.17/x64/lib/python3.10/site-packages/selenium/webdriver/remote/webdriver.py", line 447, in execute
    self.error_handler.check_response(response)
  File "/opt/hostedtoolcache/Python/3.10.17/x64/lib/python3.10/site-packages/selenium/webdriver/remote/errorhandler.py", line 232, in check_response
    raise exception_class(message, screen, stacktrace)
selenium.common.exceptions.InvalidSessionIdException: Message: invalid session id
Stacktrace:
#0 0x56545a35b71a <unknown>
#1 0x565459dfdef3 <unknown>
#2 0x565459e40f0f <unknown>
#3 0x565459e752a6 <unknown>
#4 0x565459e6fbe7 <unknown>
#5 0x565459e6ed25 <unknown>
#6 0x565459dc7a88 <unknown>
#7 0x56545a3208cb <unknown>
#8 0x56545a3247ca <unknown>
#9 0x56545a308622 <unknown>
#10 0x56545a325354 <unknown>
#11 0x56545a2ed45f <unknown>
#12 0x565459dc5821 <unknown>
#13 0x7f8bd682a1ca <unknown>
#14 0x7f8bd682a28b __libc_start_main
#15 0x565459d8d4ea _start

2025-06-08 21:36:23,277 - INFO - 🎯 [51/84] Applying to: Senior AI Solutions Architect
2025-06-08 21:36:23,284 - ERROR -    ❌ Application failed: Message: invalid session id
Stacktrace:
#0 0x56545a35b71a <unknown>
#1 0x565459dfdef3 <unknown>
#2 0x565459e40f0f <unknown>
#3 0x565459e752a6 <unknown>
#4 0x565459e6fbe7 <unknown>
#5 0x565459e6ed25 <unknown>
#6 0x565459dc7a88 <unknown>
#7 0x56545a3208cb <unknown>
#8 0x56545a3247ca <unknown>
#9 0x56545a308622 <unknown>
#10 0x56545a325354 <unknown>
#11 0x56545a2ed45f <unknown>
#12 0x565459dc5821 <unknown>
#13 0x7f8bd682a1ca <unknown>
#14 0x7f8bd682a28b __libc_start_main
#15 0x565459d8d4ea _start

2025-06-08 21:36:23,284 - ERROR - Full error for Senior AI Solutions Architect:
Traceback (most recent call last):
  File "/home/runner/work/Applier-Workflow/Applier-Workflow/scripts/src/stealth_apply.py", line 149, in easy_apply
    driver.get(job_link)
  File "/opt/hostedtoolcache/Python/3.10.17/x64/lib/python3.10/site-packages/undetected_chromedriver/__init__.py", line 496, in get_wrapped
    if self.execute_script("return navigator.webdriver"):
  File "/opt/hostedtoolcache/Python/3.10.17/x64/lib/python3.10/site-packages/selenium/webdriver/remote/webdriver.py", line 544, in execute_script
    return self.execute(command, {"script": script, "args": converted_args})["value"]
  File "/opt/hostedtoolcache/Python/3.10.17/x64/lib/python3.10/site-packages/selenium/webdriver/remote/webdriver.py", line 447, in execute
    self.error_handler.check_response(response)
  File "/opt/hostedtoolcache/Python/3.10.17/x64/lib/python3.10/site-packages/selenium/webdriver/remote/errorhandler.py", line 232, in check_response
    raise exception_class(message, screen, stacktrace)
selenium.common.exceptions.InvalidSessionIdException: Message: invalid session id
Stacktrace:
#0 0x56545a35b71a <unknown>
#1 0x565459dfdef3 <unknown>
#2 0x565459e40f0f <unknown>
#3 0x565459e752a6 <unknown>
#4 0x565459e6fbe7 <unknown>
#5 0x565459e6ed25 <unknown>
#6 0x565459dc7a88 <unknown>
#7 0x56545a3208cb <unknown>
#8 0x56545a3247ca <unknown>
#9 0x56545a308622 <unknown>
#10 0x56545a325354 <unknown>
#11 0x56545a2ed45f <unknown>
#12 0x565459dc5821 <unknown>
#13 0x7f8bd682a1ca <unknown>
#14 0x7f8bd682a28b __libc_start_main
#15 0x565459d8d4ea _start

2025-06-08 21:36:35,073 - INFO - 🎯 [52/84] Applying to: GenAI Architect
2025-06-08 21:36:35,080 - ERROR -    ❌ Application failed: Message: invalid session id
Stacktrace:
#0 0x56545a35b71a <unknown>
#1 0x565459dfdef3 <unknown>
#2 0x565459e40f0f <unknown>
#3 0x565459e752a6 <unknown>
#4 0x565459e6fbe7 <unknown>
#5 0x565459e6ed25 <unknown>
#6 0x565459dc7a88 <unknown>
#7 0x56545a3208cb <unknown>
#8 0x56545a3247ca <unknown>
#9 0x56545a308622 <unknown>
#10 0x56545a325354 <unknown>
#11 0x56545a2ed45f <unknown>
#12 0x565459dc5821 <unknown>
#13 0x7f8bd682a1ca <unknown>
#14 0x7f8bd682a28b __libc_start_main
#15 0x565459d8d4ea _start

2025-06-08 21:36:35,080 - ERROR - Full error for GenAI Architect:
Traceback (most recent call last):
  File "/home/runner/work/Applier-Workflow/Applier-Workflow/scripts/src/stealth_apply.py", line 149, in easy_apply
    driver.get(job_link)
  File "/opt/hostedtoolcache/Python/3.10.17/x64/lib/python3.10/site-packages/undetected_chromedriver/__init__.py", line 496, in get_wrapped
    if self.execute_script("return navigator.webdriver"):
  File "/opt/hostedtoolcache/Python/3.10.17/x64/lib/python3.10/site-packages/selenium/webdriver/remote/webdriver.py", line 544, in execute_script
    return self.execute(command, {"script": script, "args": converted_args})["value"]
  File "/opt/hostedtoolcache/Python/3.10.17/x64/lib/python3.10/site-packages/selenium/webdriver/remote/webdriver.py", line 447, in execute
    self.error_handler.check_response(response)
  File "/opt/hostedtoolcache/Python/3.10.17/x64/lib/python3.10/site-packages/selenium/webdriver/remote/errorhandler.py", line 232, in check_response
    raise exception_class(message, screen, stacktrace)
selenium.common.exceptions.InvalidSessionIdException: Message: invalid session id
Stacktrace:
#0 0x56545a35b71a <unknown>
#1 0x565459dfdef3 <unknown>
#2 0x565459e40f0f <unknown>
#3 0x565459e752a6 <unknown>
#4 0x565459e6fbe7 <unknown>
#5 0x565459e6ed25 <unknown>
#6 0x565459dc7a88 <unknown>
#7 0x56545a3208cb <unknown>
#8 0x56545a3247ca <unknown>
#9 0x56545a308622 <unknown>
#10 0x56545a325354 <unknown>
#11 0x56545a2ed45f <unknown>
#12 0x565459dc5821 <unknown>
#13 0x7f8bd682a1ca <unknown>
#14 0x7f8bd682a28b __libc_start_main
#15 0x565459d8d4ea _start

2025-06-08 21:36:42,658 - INFO - 🎯 [53/84] Applying to: AI Engineer
2025-06-08 21:36:42,666 - ERROR -    ❌ Application failed: Message: invalid session id
Stacktrace:
#0 0x56545a35b71a <unknown>
#1 0x565459dfdef3 <unknown>
#2 0x565459e40f0f <unknown>
#3 0x565459e752a6 <unknown>
#4 0x565459e6fbe7 <unknown>
#5 0x565459e6ed25 <unknown>
#6 0x565459dc7a88 <unknown>
#7 0x56545a3208cb <unknown>
#8 0x56545a3247ca <unknown>
#9 0x56545a308622 <unknown>
#10 0x56545a325354 <unknown>
#11 0x56545a2ed45f <unknown>
#12 0x565459dc5821 <unknown>
#13 0x7f8bd682a1ca <unknown>
#14 0x7f8bd682a28b __libc_start_main
#15 0x565459d8d4ea _start

2025-06-08 21:36:42,666 - ERROR - Full error for AI Engineer:
Traceback (most recent call last):
  File "/home/runner/work/Applier-Workflow/Applier-Workflow/scripts/src/stealth_apply.py", line 149, in easy_apply
    driver.get(job_link)
  File "/opt/hostedtoolcache/Python/3.10.17/x64/lib/python3.10/site-packages/undetected_chromedriver/__init__.py", line 496, in get_wrapped
    if self.execute_script("return navigator.webdriver"):
  File "/opt/hostedtoolcache/Python/3.10.17/x64/lib/python3.10/site-packages/selenium/webdriver/remote/webdriver.py", line 544, in execute_script
    return self.execute(command, {"script": script, "args": converted_args})["value"]
  File "/opt/hostedtoolcache/Python/3.10.17/x64/lib/python3.10/site-packages/selenium/webdriver/remote/webdriver.py", line 447, in execute
    self.error_handler.check_response(response)
  File "/opt/hostedtoolcache/Python/3.10.17/x64/lib/python3.10/site-packages/selenium/webdriver/remote/errorhandler.py", line 232, in check_response
    raise exception_class(message, screen, stacktrace)
selenium.common.exceptions.InvalidSessionIdException: Message: invalid session id
Stacktrace:
#0 0x56545a35b71a <unknown>
#1 0x565459dfdef3 <unknown>
#2 0x565459e40f0f <unknown>
#3 0x565459e752a6 <unknown>
#4 0x565459e6fbe7 <unknown>
#5 0x565459e6ed25 <unknown>
#6 0x565459dc7a88 <unknown>
#7 0x56545a3208cb <unknown>
#8 0x56545a3247ca <unknown>
#9 0x56545a308622 <unknown>
#10 0x56545a325354 <unknown>
#11 0x56545a2ed45f <unknown>
#12 0x565459dc5821 <unknown>
#13 0x7f8bd682a1ca <unknown>
#14 0x7f8bd682a28b __libc_start_main
#15 0x565459d8d4ea _start

2025-06-08 21:36:51,355 - INFO - 🎯 [54/84] Applying to: Data Platform Lead- Local, In-Office
2025-06-08 21:36:51,362 - ERROR -    ❌ Application failed: Message: invalid session id
Stacktrace:
#0 0x56545a35b71a <unknown>
#1 0x565459dfdef3 <unknown>
#2 0x565459e40f0f <unknown>
#3 0x565459e752a6 <unknown>
#4 0x565459e6fbe7 <unknown>
#5 0x565459e6ed25 <unknown>
#6 0x565459dc7a88 <unknown>
#7 0x56545a3208cb <unknown>
#8 0x56545a3247ca <unknown>
#9 0x56545a308622 <unknown>
#10 0x56545a325354 <unknown>
#11 0x56545a2ed45f <unknown>
#12 0x565459dc5821 <unknown>
#13 0x7f8bd682a1ca <unknown>
#14 0x7f8bd682a28b __libc_start_main
#15 0x565459d8d4ea _start

2025-06-08 21:36:51,362 - ERROR - Full error for Data Platform Lead- Local, In-Office:
Traceback (most recent call last):
  File "/home/runner/work/Applier-Workflow/Applier-Workflow/scripts/src/stealth_apply.py", line 149, in easy_apply
    driver.get(job_link)
  File "/opt/hostedtoolcache/Python/3.10.17/x64/lib/python3.10/site-packages/undetected_chromedriver/__init__.py", line 496, in get_wrapped
    if self.execute_script("return navigator.webdriver"):
  File "/opt/hostedtoolcache/Python/3.10.17/x64/lib/python3.10/site-packages/selenium/webdriver/remote/webdriver.py", line 544, in execute_script
    return self.execute(command, {"script": script, "args": converted_args})["value"]
  File "/opt/hostedtoolcache/Python/3.10.17/x64/lib/python3.10/site-packages/selenium/webdriver/remote/webdriver.py", line 447, in execute
    self.error_handler.check_response(response)
  File "/opt/hostedtoolcache/Python/3.10.17/x64/lib/python3.10/site-packages/selenium/webdriver/remote/errorhandler.py", line 232, in check_response
    raise exception_class(message, screen, stacktrace)
selenium.common.exceptions.InvalidSessionIdException: Message: invalid session id
Stacktrace:
#0 0x56545a35b71a <unknown>
#1 0x565459dfdef3 <unknown>
#2 0x565459e40f0f <unknown>
#3 0x565459e752a6 <unknown>
#4 0x565459e6fbe7 <unknown>
#5 0x565459e6ed25 <unknown>
#6 0x565459dc7a88 <unknown>
#7 0x56545a3208cb <unknown>
#8 0x56545a3247ca <unknown>
#9 0x56545a308622 <unknown>
#10 0x56545a325354 <unknown>
#11 0x56545a2ed45f <unknown>
#12 0x565459dc5821 <unknown>
#13 0x7f8bd682a1ca <unknown>
#14 0x7f8bd682a28b __libc_start_main
#15 0x565459d8d4ea _start

2025-06-08 21:36:59,701 - INFO - 🎯 [55/84] Applying to: Senior Data Scientist
2025-06-08 21:36:59,708 - ERROR -    ❌ Application failed: Message: invalid session id
Stacktrace:
#0 0x56545a35b71a <unknown>
#1 0x565459dfdef3 <unknown>
#2 0x565459e40f0f <unknown>
#3 0x565459e752a6 <unknown>
#4 0x565459e6fbe7 <unknown>
#5 0x565459e6ed25 <unknown>
#6 0x565459dc7a88 <unknown>
#7 0x56545a3208cb <unknown>
#8 0x56545a3247ca <unknown>
#9 0x56545a308622 <unknown>
#10 0x56545a325354 <unknown>
#11 0x56545a2ed45f <unknown>
#12 0x565459dc5821 <unknown>
#13 0x7f8bd682a1ca <unknown>
#14 0x7f8bd682a28b __libc_start_main
#15 0x565459d8d4ea _start

2025-06-08 21:36:59,708 - ERROR - Full error for Senior Data Scientist:
Traceback (most recent call last):
  File "/home/runner/work/Applier-Workflow/Applier-Workflow/scripts/src/stealth_apply.py", line 149, in easy_apply
    driver.get(job_link)
  File "/opt/hostedtoolcache/Python/3.10.17/x64/lib/python3.10/site-packages/undetected_chromedriver/__init__.py", line 496, in get_wrapped
    if self.execute_script("return navigator.webdriver"):
  File "/opt/hostedtoolcache/Python/3.10.17/x64/lib/python3.10/site-packages/selenium/webdriver/remote/webdriver.py", line 544, in execute_script
    return self.execute(command, {"script": script, "args": converted_args})["value"]
  File "/opt/hostedtoolcache/Python/3.10.17/x64/lib/python3.10/site-packages/selenium/webdriver/remote/webdriver.py", line 447, in execute
    self.error_handler.check_response(response)
  File "/opt/hostedtoolcache/Python/3.10.17/x64/lib/python3.10/site-packages/selenium/webdriver/remote/errorhandler.py", line 232, in check_response
    raise exception_class(message, screen, stacktrace)
selenium.common.exceptions.InvalidSessionIdException: Message: invalid session id
Stacktrace:
#0 0x56545a35b71a <unknown>
#1 0x565459dfdef3 <unknown>
#2 0x565459e40f0f <unknown>
#3 0x565459e752a6 <unknown>
#4 0x565459e6fbe7 <unknown>
#5 0x565459e6ed25 <unknown>
#6 0x565459dc7a88 <unknown>
#7 0x56545a3208cb <unknown>
#8 0x56545a3247ca <unknown>
#9 0x56545a308622 <unknown>
#10 0x56545a325354 <unknown>
#11 0x56545a2ed45f <unknown>
#12 0x565459dc5821 <unknown>
#13 0x7f8bd682a1ca <unknown>
#14 0x7f8bd682a28b __libc_start_main
#15 0x565459d8d4ea _start

2025-06-08 21:37:06,848 - INFO - 🎯 [56/84] Applying to: Digital or Speech AI Engineer with IVR & Speech Tuning | Remote
2025-06-08 21:37:06,855 - ERROR -    ❌ Application failed: Message: invalid session id
Stacktrace:
#0 0x56545a35b71a <unknown>
#1 0x565459dfdef3 <unknown>
#2 0x565459e40f0f <unknown>
#3 0x565459e752a6 <unknown>
#4 0x565459e6fbe7 <unknown>
#5 0x565459e6ed25 <unknown>
#6 0x565459dc7a88 <unknown>
#7 0x56545a3208cb <unknown>
#8 0x56545a3247ca <unknown>
#9 0x56545a308622 <unknown>
#10 0x56545a325354 <unknown>
#11 0x56545a2ed45f <unknown>
#12 0x565459dc5821 <unknown>
#13 0x7f8bd682a1ca <unknown>
#14 0x7f8bd682a28b __libc_start_main
#15 0x565459d8d4ea _start

2025-06-08 21:37:06,855 - ERROR - Full error for Digital or Speech AI Engineer with IVR & Speech Tuning | Remote:
Traceback (most recent call last):
  File "/home/runner/work/Applier-Workflow/Applier-Workflow/scripts/src/stealth_apply.py", line 149, in easy_apply
    driver.get(job_link)
  File "/opt/hostedtoolcache/Python/3.10.17/x64/lib/python3.10/site-packages/undetected_chromedriver/__init__.py", line 496, in get_wrapped
    if self.execute_script("return navigator.webdriver"):
  File "/opt/hostedtoolcache/Python/3.10.17/x64/lib/python3.10/site-packages/selenium/webdriver/remote/webdriver.py", line 544, in execute_script
    return self.execute(command, {"script": script, "args": converted_args})["value"]
  File "/opt/hostedtoolcache/Python/3.10.17/x64/lib/python3.10/site-packages/selenium/webdriver/remote/webdriver.py", line 447, in execute
    self.error_handler.check_response(response)
  File "/opt/hostedtoolcache/Python/3.10.17/x64/lib/python3.10/site-packages/selenium/webdriver/remote/errorhandler.py", line 232, in check_response
    raise exception_class(message, screen, stacktrace)
selenium.common.exceptions.InvalidSessionIdException: Message: invalid session id
Stacktrace:
#0 0x56545a35b71a <unknown>
#1 0x565459dfdef3 <unknown>
#2 0x565459e40f0f <unknown>
#3 0x565459e752a6 <unknown>
#4 0x565459e6fbe7 <unknown>
#5 0x565459e6ed25 <unknown>
#6 0x565459dc7a88 <unknown>
#7 0x56545a3208cb <unknown>
#8 0x56545a3247ca <unknown>
#9 0x56545a308622 <unknown>
#10 0x56545a325354 <unknown>
#11 0x56545a2ed45f <unknown>
#12 0x565459dc5821 <unknown>
#13 0x7f8bd682a1ca <unknown>
#14 0x7f8bd682a28b __libc_start_main
#15 0x565459d8d4ea _start

2025-06-08 21:37:14,828 - INFO - 🎯 [57/84] Applying to: Generative AI Developer-Microsoft Stack (Python)
2025-06-08 21:37:14,836 - ERROR -    ❌ Application failed: Message: invalid session id
Stacktrace:
#0 0x56545a35b71a <unknown>
#1 0x565459dfdef3 <unknown>
#2 0x565459e40f0f <unknown>
#3 0x565459e752a6 <unknown>
#4 0x565459e6fbe7 <unknown>
#5 0x565459e6ed25 <unknown>
#6 0x565459dc7a88 <unknown>
#7 0x56545a3208cb <unknown>
#8 0x56545a3247ca <unknown>
#9 0x56545a308622 <unknown>
#10 0x56545a325354 <unknown>
#11 0x56545a2ed45f <unknown>
#12 0x565459dc5821 <unknown>
#13 0x7f8bd682a1ca <unknown>
#14 0x7f8bd682a28b __libc_start_main
#15 0x565459d8d4ea _start

2025-06-08 21:37:14,836 - ERROR - Full error for Generative AI Developer-Microsoft Stack (Python):
Traceback (most recent call last):
  File "/home/runner/work/Applier-Workflow/Applier-Workflow/scripts/src/stealth_apply.py", line 149, in easy_apply
    driver.get(job_link)
  File "/opt/hostedtoolcache/Python/3.10.17/x64/lib/python3.10/site-packages/undetected_chromedriver/__init__.py", line 496, in get_wrapped
    if self.execute_script("return navigator.webdriver"):
  File "/opt/hostedtoolcache/Python/3.10.17/x64/lib/python3.10/site-packages/selenium/webdriver/remote/webdriver.py", line 544, in execute_script
    return self.execute(command, {"script": script, "args": converted_args})["value"]
  File "/opt/hostedtoolcache/Python/3.10.17/x64/lib/python3.10/site-packages/selenium/webdriver/remote/webdriver.py", line 447, in execute
    self.error_handler.check_response(response)
  File "/opt/hostedtoolcache/Python/3.10.17/x64/lib/python3.10/site-packages/selenium/webdriver/remote/errorhandler.py", line 232, in check_response
    raise exception_class(message, screen, stacktrace)
selenium.common.exceptions.InvalidSessionIdException: Message: invalid session id
Stacktrace:
#0 0x56545a35b71a <unknown>
#1 0x565459dfdef3 <unknown>
#2 0x565459e40f0f <unknown>
#3 0x565459e752a6 <unknown>
#4 0x565459e6fbe7 <unknown>
#5 0x565459e6ed25 <unknown>
#6 0x565459dc7a88 <unknown>
#7 0x56545a3208cb <unknown>
#8 0x56545a3247ca <unknown>
#9 0x56545a308622 <unknown>
#10 0x56545a325354 <unknown>
#11 0x56545a2ed45f <unknown>
#12 0x565459dc5821 <unknown>
#13 0x7f8bd682a1ca <unknown>
#14 0x7f8bd682a28b __libc_start_main
#15 0x565459d8d4ea _start

2025-06-08 21:37:22,763 - INFO - 🎯 [58/84] Applying to: Azure Data Engineer
2025-06-08 21:37:22,770 - ERROR -    ❌ Application failed: Message: invalid session id
Stacktrace:
#0 0x56545a35b71a <unknown>
#1 0x565459dfdef3 <unknown>
#2 0x565459e40f0f <unknown>
#3 0x565459e752a6 <unknown>
#4 0x565459e6fbe7 <unknown>
#5 0x565459e6ed25 <unknown>
#6 0x565459dc7a88 <unknown>
#7 0x56545a3208cb <unknown>
#8 0x56545a3247ca <unknown>
#9 0x56545a308622 <unknown>
#10 0x56545a325354 <unknown>
#11 0x56545a2ed45f <unknown>
#12 0x565459dc5821 <unknown>
#13 0x7f8bd682a1ca <unknown>
#14 0x7f8bd682a28b __libc_start_main
#15 0x565459d8d4ea _start

2025-06-08 21:37:22,770 - ERROR - Full error for Azure Data Engineer:
Traceback (most recent call last):
  File "/home/runner/work/Applier-Workflow/Applier-Workflow/scripts/src/stealth_apply.py", line 149, in easy_apply
    driver.get(job_link)
  File "/opt/hostedtoolcache/Python/3.10.17/x64/lib/python3.10/site-packages/undetected_chromedriver/__init__.py", line 496, in get_wrapped
    if self.execute_script("return navigator.webdriver"):
  File "/opt/hostedtoolcache/Python/3.10.17/x64/lib/python3.10/site-packages/selenium/webdriver/remote/webdriver.py", line 544, in execute_script
    return self.execute(command, {"script": script, "args": converted_args})["value"]
  File "/opt/hostedtoolcache/Python/3.10.17/x64/lib/python3.10/site-packages/selenium/webdriver/remote/webdriver.py", line 447, in execute
    self.error_handler.check_response(response)
  File "/opt/hostedtoolcache/Python/3.10.17/x64/lib/python3.10/site-packages/selenium/webdriver/remote/errorhandler.py", line 232, in check_response
    raise exception_class(message, screen, stacktrace)
selenium.common.exceptions.InvalidSessionIdException: Message: invalid session id
Stacktrace:
#0 0x56545a35b71a <unknown>
#1 0x565459dfdef3 <unknown>
#2 0x565459e40f0f <unknown>
#3 0x565459e752a6 <unknown>
#4 0x565459e6fbe7 <unknown>
#5 0x565459e6ed25 <unknown>
#6 0x565459dc7a88 <unknown>
#7 0x56545a3208cb <unknown>
#8 0x56545a3247ca <unknown>
#9 0x56545a308622 <unknown>
#10 0x56545a325354 <unknown>
#11 0x56545a2ed45f <unknown>
#12 0x565459dc5821 <unknown>
#13 0x7f8bd682a1ca <unknown>
#14 0x7f8bd682a28b __libc_start_main
#15 0x565459d8d4ea _start

2025-06-08 21:37:31,570 - INFO - 🎯 [59/84] Applying to: Gen AI engineer
2025-06-08 21:37:31,577 - ERROR -    ❌ Application failed: Message: invalid session id
Stacktrace:
#0 0x56545a35b71a <unknown>
#1 0x565459dfdef3 <unknown>
#2 0x565459e40f0f <unknown>
#3 0x565459e752a6 <unknown>
#4 0x565459e6fbe7 <unknown>
#5 0x565459e6ed25 <unknown>
#6 0x565459dc7a88 <unknown>
#7 0x56545a3208cb <unknown>
#8 0x56545a3247ca <unknown>
#9 0x56545a308622 <unknown>
#10 0x56545a325354 <unknown>
#11 0x56545a2ed45f <unknown>
#12 0x565459dc5821 <unknown>
#13 0x7f8bd682a1ca <unknown>
#14 0x7f8bd682a28b __libc_start_main
#15 0x565459d8d4ea _start

2025-06-08 21:37:31,578 - ERROR - Full error for Gen AI engineer:
Traceback (most recent call last):
  File "/home/runner/work/Applier-Workflow/Applier-Workflow/scripts/src/stealth_apply.py", line 149, in easy_apply
    driver.get(job_link)
  File "/opt/hostedtoolcache/Python/3.10.17/x64/lib/python3.10/site-packages/undetected_chromedriver/__init__.py", line 496, in get_wrapped
    if self.execute_script("return navigator.webdriver"):
  File "/opt/hostedtoolcache/Python/3.10.17/x64/lib/python3.10/site-packages/selenium/webdriver/remote/webdriver.py", line 544, in execute_script
    return self.execute(command, {"script": script, "args": converted_args})["value"]
  File "/opt/hostedtoolcache/Python/3.10.17/x64/lib/python3.10/site-packages/selenium/webdriver/remote/webdriver.py", line 447, in execute
    self.error_handler.check_response(response)
  File "/opt/hostedtoolcache/Python/3.10.17/x64/lib/python3.10/site-packages/selenium/webdriver/remote/errorhandler.py", line 232, in check_response
    raise exception_class(message, screen, stacktrace)
selenium.common.exceptions.InvalidSessionIdException: Message: invalid session id
Stacktrace:
#0 0x56545a35b71a <unknown>
#1 0x565459dfdef3 <unknown>
#2 0x565459e40f0f <unknown>
#3 0x565459e752a6 <unknown>
#4 0x565459e6fbe7 <unknown>
#5 0x565459e6ed25 <unknown>
#6 0x565459dc7a88 <unknown>
#7 0x56545a3208cb <unknown>
#8 0x56545a3247ca <unknown>
#9 0x56545a308622 <unknown>
#10 0x56545a325354 <unknown>
#11 0x56545a2ed45f <unknown>
#12 0x565459dc5821 <unknown>
#13 0x7f8bd682a1ca <unknown>
#14 0x7f8bd682a28b __libc_start_main
#15 0x565459d8d4ea _start

2025-06-08 21:37:38,667 - INFO - 🎯 [60/84] Applying to: Sr Technical Writer-Must have Machine Learning product
2025-06-08 21:37:38,675 - ERROR -    ❌ Application failed: Message: invalid session id
Stacktrace:
#0 0x56545a35b71a <unknown>
#1 0x565459dfdef3 <unknown>
#2 0x565459e40f0f <unknown>
#3 0x565459e752a6 <unknown>
#4 0x565459e6fbe7 <unknown>
#5 0x565459e6ed25 <unknown>
#6 0x565459dc7a88 <unknown>
#7 0x56545a3208cb <unknown>
#8 0x56545a3247ca <unknown>
#9 0x56545a308622 <unknown>
#10 0x56545a325354 <unknown>
#11 0x56545a2ed45f <unknown>
#12 0x565459dc5821 <unknown>
#13 0x7f8bd682a1ca <unknown>
#14 0x7f8bd682a28b __libc_start_main
#15 0x565459d8d4ea _start

2025-06-08 21:37:38,675 - ERROR - Full error for Sr Technical Writer-Must have Machine Learning product:
Traceback (most recent call last):
  File "/home/runner/work/Applier-Workflow/Applier-Workflow/scripts/src/stealth_apply.py", line 149, in easy_apply
    driver.get(job_link)
  File "/opt/hostedtoolcache/Python/3.10.17/x64/lib/python3.10/site-packages/undetected_chromedriver/__init__.py", line 496, in get_wrapped
    if self.execute_script("return navigator.webdriver"):
  File "/opt/hostedtoolcache/Python/3.10.17/x64/lib/python3.10/site-packages/selenium/webdriver/remote/webdriver.py", line 544, in execute_script
    return self.execute(command, {"script": script, "args": converted_args})["value"]
  File "/opt/hostedtoolcache/Python/3.10.17/x64/lib/python3.10/site-packages/selenium/webdriver/remote/webdriver.py", line 447, in execute
    self.error_handler.check_response(response)
  File "/opt/hostedtoolcache/Python/3.10.17/x64/lib/python3.10/site-packages/selenium/webdriver/remote/errorhandler.py", line 232, in check_response
    raise exception_class(message, screen, stacktrace)
selenium.common.exceptions.InvalidSessionIdException: Message: invalid session id
Stacktrace:
#0 0x56545a35b71a <unknown>
#1 0x565459dfdef3 <unknown>
#2 0x565459e40f0f <unknown>
#3 0x565459e752a6 <unknown>
#4 0x565459e6fbe7 <unknown>
#5 0x565459e6ed25 <unknown>
#6 0x565459dc7a88 <unknown>
#7 0x56545a3208cb <unknown>
#8 0x56545a3247ca <unknown>
#9 0x56545a308622 <unknown>
#10 0x56545a325354 <unknown>
#11 0x56545a2ed45f <unknown>
#12 0x565459dc5821 <unknown>
#13 0x7f8bd682a1ca <unknown>
#14 0x7f8bd682a28b __libc_start_main
#15 0x565459d8d4ea _start

2025-06-08 21:37:48,245 - INFO - 🎯 [61/84] Applying to: Teradata ML Data Scientist
2025-06-08 21:37:48,252 - ERROR -    ❌ Application failed: Message: invalid session id
Stacktrace:
#0 0x56545a35b71a <unknown>
#1 0x565459dfdef3 <unknown>
#2 0x565459e40f0f <unknown>
#3 0x565459e752a6 <unknown>
#4 0x565459e6fbe7 <unknown>
#5 0x565459e6ed25 <unknown>
#6 0x565459dc7a88 <unknown>
#7 0x56545a3208cb <unknown>
#8 0x56545a3247ca <unknown>
#9 0x56545a308622 <unknown>
#10 0x56545a325354 <unknown>
#11 0x56545a2ed45f <unknown>
#12 0x565459dc5821 <unknown>
#13 0x7f8bd682a1ca <unknown>
#14 0x7f8bd682a28b __libc_start_main
#15 0x565459d8d4ea _start

2025-06-08 21:37:48,252 - ERROR - Full error for Teradata ML Data Scientist:
Traceback (most recent call last):
  File "/home/runner/work/Applier-Workflow/Applier-Workflow/scripts/src/stealth_apply.py", line 149, in easy_apply
    driver.get(job_link)
  File "/opt/hostedtoolcache/Python/3.10.17/x64/lib/python3.10/site-packages/undetected_chromedriver/__init__.py", line 496, in get_wrapped
    if self.execute_script("return navigator.webdriver"):
  File "/opt/hostedtoolcache/Python/3.10.17/x64/lib/python3.10/site-packages/selenium/webdriver/remote/webdriver.py", line 544, in execute_script
    return self.execute(command, {"script": script, "args": converted_args})["value"]
  File "/opt/hostedtoolcache/Python/3.10.17/x64/lib/python3.10/site-packages/selenium/webdriver/remote/webdriver.py", line 447, in execute
    self.error_handler.check_response(response)
  File "/opt/hostedtoolcache/Python/3.10.17/x64/lib/python3.10/site-packages/selenium/webdriver/remote/errorhandler.py", line 232, in check_response
    raise exception_class(message, screen, stacktrace)
selenium.common.exceptions.InvalidSessionIdException: Message: invalid session id
Stacktrace:
#0 0x56545a35b71a <unknown>
#1 0x565459dfdef3 <unknown>
#2 0x565459e40f0f <unknown>
#3 0x565459e752a6 <unknown>
#4 0x565459e6fbe7 <unknown>
#5 0x565459e6ed25 <unknown>
#6 0x565459dc7a88 <unknown>
#7 0x56545a3208cb <unknown>
#8 0x56545a3247ca <unknown>
#9 0x56545a308622 <unknown>
#10 0x56545a325354 <unknown>
#11 0x56545a2ed45f <unknown>
#12 0x565459dc5821 <unknown>
#13 0x7f8bd682a1ca <unknown>
#14 0x7f8bd682a28b __libc_start_main
#15 0x565459d8d4ea _start

2025-06-08 21:37:57,459 - INFO - 🎯 [62/84] Applying to: AI Engineer
2025-06-08 21:37:57,466 - ERROR -    ❌ Application failed: Message: invalid session id
Stacktrace:
#0 0x56545a35b71a <unknown>
#1 0x565459dfdef3 <unknown>
#2 0x565459e40f0f <unknown>
#3 0x565459e752a6 <unknown>
#4 0x565459e6fbe7 <unknown>
#5 0x565459e6ed25 <unknown>
#6 0x565459dc7a88 <unknown>
#7 0x56545a3208cb <unknown>
#8 0x56545a3247ca <unknown>
#9 0x56545a308622 <unknown>
#10 0x56545a325354 <unknown>
#11 0x56545a2ed45f <unknown>
#12 0x565459dc5821 <unknown>
#13 0x7f8bd682a1ca <unknown>
#14 0x7f8bd682a28b __libc_start_main
#15 0x565459d8d4ea _start

2025-06-08 21:37:57,467 - ERROR - Full error for AI Engineer:
Traceback (most recent call last):
  File "/home/runner/work/Applier-Workflow/Applier-Workflow/scripts/src/stealth_apply.py", line 149, in easy_apply
    driver.get(job_link)
  File "/opt/hostedtoolcache/Python/3.10.17/x64/lib/python3.10/site-packages/undetected_chromedriver/__init__.py", line 496, in get_wrapped
    if self.execute_script("return navigator.webdriver"):
  File "/opt/hostedtoolcache/Python/3.10.17/x64/lib/python3.10/site-packages/selenium/webdriver/remote/webdriver.py", line 544, in execute_script
    return self.execute(command, {"script": script, "args": converted_args})["value"]
  File "/opt/hostedtoolcache/Python/3.10.17/x64/lib/python3.10/site-packages/selenium/webdriver/remote/webdriver.py", line 447, in execute
    self.error_handler.check_response(response)
  File "/opt/hostedtoolcache/Python/3.10.17/x64/lib/python3.10/site-packages/selenium/webdriver/remote/errorhandler.py", line 232, in check_response
    raise exception_class(message, screen, stacktrace)
selenium.common.exceptions.InvalidSessionIdException: Message: invalid session id
Stacktrace:
#0 0x56545a35b71a <unknown>
#1 0x565459dfdef3 <unknown>
#2 0x565459e40f0f <unknown>
#3 0x565459e752a6 <unknown>
#4 0x565459e6fbe7 <unknown>
#5 0x565459e6ed25 <unknown>
#6 0x565459dc7a88 <unknown>
#7 0x56545a3208cb <unknown>
#8 0x56545a3247ca <unknown>
#9 0x56545a308622 <unknown>
#10 0x56545a325354 <unknown>
#11 0x56545a2ed45f <unknown>
#12 0x565459dc5821 <unknown>
#13 0x7f8bd682a1ca <unknown>
#14 0x7f8bd682a28b __libc_start_main
#15 0x565459d8d4ea _start

2025-06-08 21:38:06,073 - INFO - 🎯 [63/84] Applying to: Data Scientist
2025-06-08 21:38:06,080 - ERROR -    ❌ Application failed: Message: invalid session id
Stacktrace:
#0 0x56545a35b71a <unknown>
#1 0x565459dfdef3 <unknown>
#2 0x565459e40f0f <unknown>
#3 0x565459e752a6 <unknown>
#4 0x565459e6fbe7 <unknown>
#5 0x565459e6ed25 <unknown>
#6 0x565459dc7a88 <unknown>
#7 0x56545a3208cb <unknown>
#8 0x56545a3247ca <unknown>
#9 0x56545a308622 <unknown>
#10 0x56545a325354 <unknown>
#11 0x56545a2ed45f <unknown>
#12 0x565459dc5821 <unknown>
#13 0x7f8bd682a1ca <unknown>
#14 0x7f8bd682a28b __libc_start_main
#15 0x565459d8d4ea _start

2025-06-08 21:38:06,080 - ERROR - Full error for Data Scientist:
Traceback (most recent call last):
  File "/home/runner/work/Applier-Workflow/Applier-Workflow/scripts/src/stealth_apply.py", line 149, in easy_apply
    driver.get(job_link)
  File "/opt/hostedtoolcache/Python/3.10.17/x64/lib/python3.10/site-packages/undetected_chromedriver/__init__.py", line 496, in get_wrapped
    if self.execute_script("return navigator.webdriver"):
  File "/opt/hostedtoolcache/Python/3.10.17/x64/lib/python3.10/site-packages/selenium/webdriver/remote/webdriver.py", line 544, in execute_script
    return self.execute(command, {"script": script, "args": converted_args})["value"]
  File "/opt/hostedtoolcache/Python/3.10.17/x64/lib/python3.10/site-packages/selenium/webdriver/remote/webdriver.py", line 447, in execute
    self.error_handler.check_response(response)
  File "/opt/hostedtoolcache/Python/3.10.17/x64/lib/python3.10/site-packages/selenium/webdriver/remote/errorhandler.py", line 232, in check_response
    raise exception_class(message, screen, stacktrace)
selenium.common.exceptions.InvalidSessionIdException: Message: invalid session id
Stacktrace:
#0 0x56545a35b71a <unknown>
#1 0x565459dfdef3 <unknown>
#2 0x565459e40f0f <unknown>
#3 0x565459e752a6 <unknown>
#4 0x565459e6fbe7 <unknown>
#5 0x565459e6ed25 <unknown>
#6 0x565459dc7a88 <unknown>
#7 0x56545a3208cb <unknown>
#8 0x56545a3247ca <unknown>
#9 0x56545a308622 <unknown>
#10 0x56545a325354 <unknown>
#11 0x56545a2ed45f <unknown>
#12 0x565459dc5821 <unknown>
#13 0x7f8bd682a1ca <unknown>
#14 0x7f8bd682a28b __libc_start_main
#15 0x565459d8d4ea _start

2025-06-08 21:38:15,041 - INFO - 🎯 [64/84] Applying to: AI Engineer
2025-06-08 21:38:15,048 - ERROR -    ❌ Application failed: Message: invalid session id
Stacktrace:
#0 0x56545a35b71a <unknown>
#1 0x565459dfdef3 <unknown>
#2 0x565459e40f0f <unknown>
#3 0x565459e752a6 <unknown>
#4 0x565459e6fbe7 <unknown>
#5 0x565459e6ed25 <unknown>
#6 0x565459dc7a88 <unknown>
#7 0x56545a3208cb <unknown>
#8 0x56545a3247ca <unknown>
#9 0x56545a308622 <unknown>
#10 0x56545a325354 <unknown>
#11 0x56545a2ed45f <unknown>
#12 0x565459dc5821 <unknown>
#13 0x7f8bd682a1ca <unknown>
#14 0x7f8bd682a28b __libc_start_main
#15 0x565459d8d4ea _start

2025-06-08 21:38:15,049 - ERROR - Full error for AI Engineer:
Traceback (most recent call last):
  File "/home/runner/work/Applier-Workflow/Applier-Workflow/scripts/src/stealth_apply.py", line 149, in easy_apply
    driver.get(job_link)
  File "/opt/hostedtoolcache/Python/3.10.17/x64/lib/python3.10/site-packages/undetected_chromedriver/__init__.py", line 496, in get_wrapped
    if self.execute_script("return navigator.webdriver"):
  File "/opt/hostedtoolcache/Python/3.10.17/x64/lib/python3.10/site-packages/selenium/webdriver/remote/webdriver.py", line 544, in execute_script
    return self.execute(command, {"script": script, "args": converted_args})["value"]
  File "/opt/hostedtoolcache/Python/3.10.17/x64/lib/python3.10/site-packages/selenium/webdriver/remote/webdriver.py", line 447, in execute
    self.error_handler.check_response(response)
  File "/opt/hostedtoolcache/Python/3.10.17/x64/lib/python3.10/site-packages/selenium/webdriver/remote/errorhandler.py", line 232, in check_response
    raise exception_class(message, screen, stacktrace)
selenium.common.exceptions.InvalidSessionIdException: Message: invalid session id
Stacktrace:
#0 0x56545a35b71a <unknown>
#1 0x565459dfdef3 <unknown>
#2 0x565459e40f0f <unknown>
#3 0x565459e752a6 <unknown>
#4 0x565459e6fbe7 <unknown>
#5 0x565459e6ed25 <unknown>
#6 0x565459dc7a88 <unknown>
#7 0x56545a3208cb <unknown>
#8 0x56545a3247ca <unknown>
#9 0x56545a308622 <unknown>
#10 0x56545a325354 <unknown>
#11 0x56545a2ed45f <unknown>
#12 0x565459dc5821 <unknown>
#13 0x7f8bd682a1ca <unknown>
#14 0x7f8bd682a28b __libc_start_main
#15 0x565459d8d4ea _start

2025-06-08 21:38:24,379 - INFO - 🎯 [65/84] Applying to: AWS Data Engineer
2025-06-08 21:38:24,386 - ERROR -    ❌ Application failed: Message: invalid session id
Stacktrace:
#0 0x56545a35b71a <unknown>
#1 0x565459dfdef3 <unknown>
#2 0x565459e40f0f <unknown>
#3 0x565459e752a6 <unknown>
#4 0x565459e6fbe7 <unknown>
#5 0x565459e6ed25 <unknown>
#6 0x565459dc7a88 <unknown>
#7 0x56545a3208cb <unknown>
#8 0x56545a3247ca <unknown>
#9 0x56545a308622 <unknown>
#10 0x56545a325354 <unknown>
#11 0x56545a2ed45f <unknown>
#12 0x565459dc5821 <unknown>
#13 0x7f8bd682a1ca <unknown>
#14 0x7f8bd682a28b __libc_start_main
#15 0x565459d8d4ea _start

2025-06-08 21:38:24,386 - ERROR - Full error for AWS Data Engineer:
Traceback (most recent call last):
  File "/home/runner/work/Applier-Workflow/Applier-Workflow/scripts/src/stealth_apply.py", line 149, in easy_apply
    driver.get(job_link)
  File "/opt/hostedtoolcache/Python/3.10.17/x64/lib/python3.10/site-packages/undetected_chromedriver/__init__.py", line 496, in get_wrapped
    if self.execute_script("return navigator.webdriver"):
  File "/opt/hostedtoolcache/Python/3.10.17/x64/lib/python3.10/site-packages/selenium/webdriver/remote/webdriver.py", line 544, in execute_script
    return self.execute(command, {"script": script, "args": converted_args})["value"]
  File "/opt/hostedtoolcache/Python/3.10.17/x64/lib/python3.10/site-packages/selenium/webdriver/remote/webdriver.py", line 447, in execute
    self.error_handler.check_response(response)
  File "/opt/hostedtoolcache/Python/3.10.17/x64/lib/python3.10/site-packages/selenium/webdriver/remote/errorhandler.py", line 232, in check_response
    raise exception_class(message, screen, stacktrace)
selenium.common.exceptions.InvalidSessionIdException: Message: invalid session id
Stacktrace:
#0 0x56545a35b71a <unknown>
#1 0x565459dfdef3 <unknown>
#2 0x565459e40f0f <unknown>
#3 0x565459e752a6 <unknown>
#4 0x565459e6fbe7 <unknown>
#5 0x565459e6ed25 <unknown>
#6 0x565459dc7a88 <unknown>
#7 0x56545a3208cb <unknown>
#8 0x56545a3247ca <unknown>
#9 0x56545a308622 <unknown>
#10 0x56545a325354 <unknown>
#11 0x56545a2ed45f <unknown>
#12 0x565459dc5821 <unknown>
#13 0x7f8bd682a1ca <unknown>
#14 0x7f8bd682a28b __libc_start_main
#15 0x565459d8d4ea _start

2025-06-08 21:38:33,158 - INFO - 🎯 [66/84] Applying to: AI Business Intelligence Developer
2025-06-08 21:38:33,165 - ERROR -    ❌ Application failed: Message: invalid session id
Stacktrace:
#0 0x56545a35b71a <unknown>
#1 0x565459dfdef3 <unknown>
#2 0x565459e40f0f <unknown>
#3 0x565459e752a6 <unknown>
#4 0x565459e6fbe7 <unknown>
#5 0x565459e6ed25 <unknown>
#6 0x565459dc7a88 <unknown>
#7 0x56545a3208cb <unknown>
#8 0x56545a3247ca <unknown>
#9 0x56545a308622 <unknown>
#10 0x56545a325354 <unknown>
#11 0x56545a2ed45f <unknown>
#12 0x565459dc5821 <unknown>
#13 0x7f8bd682a1ca <unknown>
#14 0x7f8bd682a28b __libc_start_main
#15 0x565459d8d4ea _start

2025-06-08 21:38:33,165 - ERROR - Full error for AI Business Intelligence Developer:
Traceback (most recent call last):
  File "/home/runner/work/Applier-Workflow/Applier-Workflow/scripts/src/stealth_apply.py", line 149, in easy_apply
    driver.get(job_link)
  File "/opt/hostedtoolcache/Python/3.10.17/x64/lib/python3.10/site-packages/undetected_chromedriver/__init__.py", line 496, in get_wrapped
    if self.execute_script("return navigator.webdriver"):
  File "/opt/hostedtoolcache/Python/3.10.17/x64/lib/python3.10/site-packages/selenium/webdriver/remote/webdriver.py", line 544, in execute_script
    return self.execute(command, {"script": script, "args": converted_args})["value"]
  File "/opt/hostedtoolcache/Python/3.10.17/x64/lib/python3.10/site-packages/selenium/webdriver/remote/webdriver.py", line 447, in execute
    self.error_handler.check_response(response)
  File "/opt/hostedtoolcache/Python/3.10.17/x64/lib/python3.10/site-packages/selenium/webdriver/remote/errorhandler.py", line 232, in check_response
    raise exception_class(message, screen, stacktrace)
selenium.common.exceptions.InvalidSessionIdException: Message: invalid session id
Stacktrace:
#0 0x56545a35b71a <unknown>
#1 0x565459dfdef3 <unknown>
#2 0x565459e40f0f <unknown>
#3 0x565459e752a6 <unknown>
#4 0x565459e6fbe7 <unknown>
#5 0x565459e6ed25 <unknown>
#6 0x565459dc7a88 <unknown>
#7 0x56545a3208cb <unknown>
#8 0x56545a3247ca <unknown>
#9 0x56545a308622 <unknown>
#10 0x56545a325354 <unknown>
#11 0x56545a2ed45f <unknown>
#12 0x565459dc5821 <unknown>
#13 0x7f8bd682a1ca <unknown>
#14 0x7f8bd682a28b __libc_start_main
#15 0x565459d8d4ea _start

2025-06-08 21:38:41,927 - INFO - 🎯 [67/84] Applying to: Jr. ML/Data Engineer
2025-06-08 21:38:41,934 - ERROR -    ❌ Application failed: Message: invalid session id
Stacktrace:
#0 0x56545a35b71a <unknown>
#1 0x565459dfdef3 <unknown>
#2 0x565459e40f0f <unknown>
#3 0x565459e752a6 <unknown>
#4 0x565459e6fbe7 <unknown>
#5 0x565459e6ed25 <unknown>
#6 0x565459dc7a88 <unknown>
#7 0x56545a3208cb <unknown>
#8 0x56545a3247ca <unknown>
#9 0x56545a308622 <unknown>
#10 0x56545a325354 <unknown>
#11 0x56545a2ed45f <unknown>
#12 0x565459dc5821 <unknown>
#13 0x7f8bd682a1ca <unknown>
#14 0x7f8bd682a28b __libc_start_main
#15 0x565459d8d4ea _start

2025-06-08 21:38:41,934 - ERROR - Full error for Jr. ML/Data Engineer:
Traceback (most recent call last):
  File "/home/runner/work/Applier-Workflow/Applier-Workflow/scripts/src/stealth_apply.py", line 149, in easy_apply
    driver.get(job_link)
  File "/opt/hostedtoolcache/Python/3.10.17/x64/lib/python3.10/site-packages/undetected_chromedriver/__init__.py", line 496, in get_wrapped
    if self.execute_script("return navigator.webdriver"):
  File "/opt/hostedtoolcache/Python/3.10.17/x64/lib/python3.10/site-packages/selenium/webdriver/remote/webdriver.py", line 544, in execute_script
    return self.execute(command, {"script": script, "args": converted_args})["value"]
  File "/opt/hostedtoolcache/Python/3.10.17/x64/lib/python3.10/site-packages/selenium/webdriver/remote/webdriver.py", line 447, in execute
    self.error_handler.check_response(response)
  File "/opt/hostedtoolcache/Python/3.10.17/x64/lib/python3.10/site-packages/selenium/webdriver/remote/errorhandler.py", line 232, in check_response
    raise exception_class(message, screen, stacktrace)
selenium.common.exceptions.InvalidSessionIdException: Message: invalid session id
Stacktrace:
#0 0x56545a35b71a <unknown>
#1 0x565459dfdef3 <unknown>
#2 0x565459e40f0f <unknown>
#3 0x565459e752a6 <unknown>
#4 0x565459e6fbe7 <unknown>
#5 0x565459e6ed25 <unknown>
#6 0x565459dc7a88 <unknown>
#7 0x56545a3208cb <unknown>
#8 0x56545a3247ca <unknown>
#9 0x56545a308622 <unknown>
#10 0x56545a325354 <unknown>
#11 0x56545a2ed45f <unknown>
#12 0x565459dc5821 <unknown>
#13 0x7f8bd682a1ca <unknown>
#14 0x7f8bd682a28b __libc_start_main
#15 0x565459d8d4ea _start

2025-06-08 21:38:50,780 - INFO - 🎯 [68/84] Applying to: AI/ML & Gen AI Senior Engineer
2025-06-08 21:38:50,787 - ERROR -    ❌ Application failed: Message: invalid session id
Stacktrace:
#0 0x56545a35b71a <unknown>
#1 0x565459dfdef3 <unknown>
#2 0x565459e40f0f <unknown>
#3 0x565459e752a6 <unknown>
#4 0x565459e6fbe7 <unknown>
#5 0x565459e6ed25 <unknown>
#6 0x565459dc7a88 <unknown>
#7 0x56545a3208cb <unknown>
#8 0x56545a3247ca <unknown>
#9 0x56545a308622 <unknown>
#10 0x56545a325354 <unknown>
#11 0x56545a2ed45f <unknown>
#12 0x565459dc5821 <unknown>
#13 0x7f8bd682a1ca <unknown>
#14 0x7f8bd682a28b __libc_start_main
#15 0x565459d8d4ea _start

2025-06-08 21:38:50,787 - ERROR - Full error for AI/ML & Gen AI Senior Engineer:
Traceback (most recent call last):
  File "/home/runner/work/Applier-Workflow/Applier-Workflow/scripts/src/stealth_apply.py", line 149, in easy_apply
    driver.get(job_link)
  File "/opt/hostedtoolcache/Python/3.10.17/x64/lib/python3.10/site-packages/undetected_chromedriver/__init__.py", line 496, in get_wrapped
    if self.execute_script("return navigator.webdriver"):
  File "/opt/hostedtoolcache/Python/3.10.17/x64/lib/python3.10/site-packages/selenium/webdriver/remote/webdriver.py", line 544, in execute_script
    return self.execute(command, {"script": script, "args": converted_args})["value"]
  File "/opt/hostedtoolcache/Python/3.10.17/x64/lib/python3.10/site-packages/selenium/webdriver/remote/webdriver.py", line 447, in execute
    self.error_handler.check_response(response)
  File "/opt/hostedtoolcache/Python/3.10.17/x64/lib/python3.10/site-packages/selenium/webdriver/remote/errorhandler.py", line 232, in check_response
    raise exception_class(message, screen, stacktrace)
selenium.common.exceptions.InvalidSessionIdException: Message: invalid session id
Stacktrace:
#0 0x56545a35b71a <unknown>
#1 0x565459dfdef3 <unknown>
#2 0x565459e40f0f <unknown>
#3 0x565459e752a6 <unknown>
#4 0x565459e6fbe7 <unknown>
#5 0x565459e6ed25 <unknown>
#6 0x565459dc7a88 <unknown>
#7 0x56545a3208cb <unknown>
#8 0x56545a3247ca <unknown>
#9 0x56545a308622 <unknown>
#10 0x56545a325354 <unknown>
#11 0x56545a2ed45f <unknown>
#12 0x565459dc5821 <unknown>
#13 0x7f8bd682a1ca <unknown>
#14 0x7f8bd682a28b __libc_start_main
#15 0x565459d8d4ea _start

2025-06-08 21:39:03,460 - INFO - 🎯 [69/84] Applying to: Senior .NET Developer / Generative AI / Hybrid / Irving, TX
2025-06-08 21:39:03,467 - ERROR -    ❌ Application failed: Message: invalid session id
Stacktrace:
#0 0x56545a35b71a <unknown>
#1 0x565459dfdef3 <unknown>
#2 0x565459e40f0f <unknown>
#3 0x565459e752a6 <unknown>
#4 0x565459e6fbe7 <unknown>
#5 0x565459e6ed25 <unknown>
#6 0x565459dc7a88 <unknown>
#7 0x56545a3208cb <unknown>
#8 0x56545a3247ca <unknown>
#9 0x56545a308622 <unknown>
#10 0x56545a325354 <unknown>
#11 0x56545a2ed45f <unknown>
#12 0x565459dc5821 <unknown>
#13 0x7f8bd682a1ca <unknown>
#14 0x7f8bd682a28b __libc_start_main
#15 0x565459d8d4ea _start

2025-06-08 21:39:03,467 - ERROR - Full error for Senior .NET Developer / Generative AI / Hybrid / Irving, TX:
Traceback (most recent call last):
  File "/home/runner/work/Applier-Workflow/Applier-Workflow/scripts/src/stealth_apply.py", line 149, in easy_apply
    driver.get(job_link)
  File "/opt/hostedtoolcache/Python/3.10.17/x64/lib/python3.10/site-packages/undetected_chromedriver/__init__.py", line 496, in get_wrapped
    if self.execute_script("return navigator.webdriver"):
  File "/opt/hostedtoolcache/Python/3.10.17/x64/lib/python3.10/site-packages/selenium/webdriver/remote/webdriver.py", line 544, in execute_script
    return self.execute(command, {"script": script, "args": converted_args})["value"]
  File "/opt/hostedtoolcache/Python/3.10.17/x64/lib/python3.10/site-packages/selenium/webdriver/remote/webdriver.py", line 447, in execute
    self.error_handler.check_response(response)
  File "/opt/hostedtoolcache/Python/3.10.17/x64/lib/python3.10/site-packages/selenium/webdriver/remote/errorhandler.py", line 232, in check_response
    raise exception_class(message, screen, stacktrace)
selenium.common.exceptions.InvalidSessionIdException: Message: invalid session id
Stacktrace:
#0 0x56545a35b71a <unknown>
#1 0x565459dfdef3 <unknown>
#2 0x565459e40f0f <unknown>
#3 0x565459e752a6 <unknown>
#4 0x565459e6fbe7 <unknown>
#5 0x565459e6ed25 <unknown>
#6 0x565459dc7a88 <unknown>
#7 0x56545a3208cb <unknown>
#8 0x56545a3247ca <unknown>
#9 0x56545a308622 <unknown>
#10 0x56545a325354 <unknown>
#11 0x56545a2ed45f <unknown>
#12 0x565459dc5821 <unknown>
#13 0x7f8bd682a1ca <unknown>
#14 0x7f8bd682a28b __libc_start_main
#15 0x565459d8d4ea _start

2025-06-08 21:39:11,033 - INFO - 🎯 [70/84] Applying to: Platform Support AI Trainer
2025-06-08 21:39:11,041 - ERROR -    ❌ Application failed: Message: invalid session id
Stacktrace:
#0 0x56545a35b71a <unknown>
#1 0x565459dfdef3 <unknown>
#2 0x565459e40f0f <unknown>
#3 0x565459e752a6 <unknown>
#4 0x565459e6fbe7 <unknown>
#5 0x565459e6ed25 <unknown>
#6 0x565459dc7a88 <unknown>
#7 0x56545a3208cb <unknown>
#8 0x56545a3247ca <unknown>
#9 0x56545a308622 <unknown>
#10 0x56545a325354 <unknown>
#11 0x56545a2ed45f <unknown>
#12 0x565459dc5821 <unknown>
#13 0x7f8bd682a1ca <unknown>
#14 0x7f8bd682a28b __libc_start_main
#15 0x565459d8d4ea _start

2025-06-08 21:39:11,041 - ERROR - Full error for Platform Support AI Trainer:
Traceback (most recent call last):
  File "/home/runner/work/Applier-Workflow/Applier-Workflow/scripts/src/stealth_apply.py", line 149, in easy_apply
    driver.get(job_link)
  File "/opt/hostedtoolcache/Python/3.10.17/x64/lib/python3.10/site-packages/undetected_chromedriver/__init__.py", line 496, in get_wrapped
    if self.execute_script("return navigator.webdriver"):
  File "/opt/hostedtoolcache/Python/3.10.17/x64/lib/python3.10/site-packages/selenium/webdriver/remote/webdriver.py", line 544, in execute_script
    return self.execute(command, {"script": script, "args": converted_args})["value"]
  File "/opt/hostedtoolcache/Python/3.10.17/x64/lib/python3.10/site-packages/selenium/webdriver/remote/webdriver.py", line 447, in execute
    self.error_handler.check_response(response)
  File "/opt/hostedtoolcache/Python/3.10.17/x64/lib/python3.10/site-packages/selenium/webdriver/remote/errorhandler.py", line 232, in check_response
    raise exception_class(message, screen, stacktrace)
selenium.common.exceptions.InvalidSessionIdException: Message: invalid session id
Stacktrace:
#0 0x56545a35b71a <unknown>
#1 0x565459dfdef3 <unknown>
#2 0x565459e40f0f <unknown>
#3 0x565459e752a6 <unknown>
#4 0x565459e6fbe7 <unknown>
#5 0x565459e6ed25 <unknown>
#6 0x565459dc7a88 <unknown>
#7 0x56545a3208cb <unknown>
#8 0x56545a3247ca <unknown>
#9 0x56545a308622 <unknown>
#10 0x56545a325354 <unknown>
#11 0x56545a2ed45f <unknown>
#12 0x565459dc5821 <unknown>
#13 0x7f8bd682a1ca <unknown>
#14 0x7f8bd682a28b __libc_start_main
#15 0x565459d8d4ea _start

2025-06-08 21:39:21,132 - INFO - 🎯 [71/84] Applying to: Data Scientist
2025-06-08 21:39:21,139 - ERROR -    ❌ Application failed: Message: invalid session id
Stacktrace:
#0 0x56545a35b71a <unknown>
#1 0x565459dfdef3 <unknown>
#2 0x565459e40f0f <unknown>
#3 0x565459e752a6 <unknown>
#4 0x565459e6fbe7 <unknown>
#5 0x565459e6ed25 <unknown>
#6 0x565459dc7a88 <unknown>
#7 0x56545a3208cb <unknown>
#8 0x56545a3247ca <unknown>
#9 0x56545a308622 <unknown>
#10 0x56545a325354 <unknown>
#11 0x56545a2ed45f <unknown>
#12 0x565459dc5821 <unknown>
#13 0x7f8bd682a1ca <unknown>
#14 0x7f8bd682a28b __libc_start_main
#15 0x565459d8d4ea _start

2025-06-08 21:39:21,139 - ERROR - Full error for Data Scientist:
Traceback (most recent call last):
  File "/home/runner/work/Applier-Workflow/Applier-Workflow/scripts/src/stealth_apply.py", line 149, in easy_apply
    driver.get(job_link)
  File "/opt/hostedtoolcache/Python/3.10.17/x64/lib/python3.10/site-packages/undetected_chromedriver/__init__.py", line 496, in get_wrapped
    if self.execute_script("return navigator.webdriver"):
  File "/opt/hostedtoolcache/Python/3.10.17/x64/lib/python3.10/site-packages/selenium/webdriver/remote/webdriver.py", line 544, in execute_script
    return self.execute(command, {"script": script, "args": converted_args})["value"]
  File "/opt/hostedtoolcache/Python/3.10.17/x64/lib/python3.10/site-packages/selenium/webdriver/remote/webdriver.py", line 447, in execute
    self.error_handler.check_response(response)
  File "/opt/hostedtoolcache/Python/3.10.17/x64/lib/python3.10/site-packages/selenium/webdriver/remote/errorhandler.py", line 232, in check_response
    raise exception_class(message, screen, stacktrace)
selenium.common.exceptions.InvalidSessionIdException: Message: invalid session id
Stacktrace:
#0 0x56545a35b71a <unknown>
#1 0x565459dfdef3 <unknown>
#2 0x565459e40f0f <unknown>
#3 0x565459e752a6 <unknown>
#4 0x565459e6fbe7 <unknown>
#5 0x565459e6ed25 <unknown>
#6 0x565459dc7a88 <unknown>
#7 0x56545a3208cb <unknown>
#8 0x56545a3247ca <unknown>
#9 0x56545a308622 <unknown>
#10 0x56545a325354 <unknown>
#11 0x56545a2ed45f <unknown>
#12 0x565459dc5821 <unknown>
#13 0x7f8bd682a1ca <unknown>
#14 0x7f8bd682a28b __libc_start_main
#15 0x565459d8d4ea _start

2025-06-08 21:39:30,688 - INFO - 🎯 [72/84] Applying to: R Programmer/ IT - Technology Architect | data science | Machine Learning
2025-06-08 21:39:30,695 - ERROR -    ❌ Application failed: Message: invalid session id
Stacktrace:
#0 0x56545a35b71a <unknown>
#1 0x565459dfdef3 <unknown>
#2 0x565459e40f0f <unknown>
#3 0x565459e752a6 <unknown>
#4 0x565459e6fbe7 <unknown>
#5 0x565459e6ed25 <unknown>
#6 0x565459dc7a88 <unknown>
#7 0x56545a3208cb <unknown>
#8 0x56545a3247ca <unknown>
#9 0x56545a308622 <unknown>
#10 0x56545a325354 <unknown>
#11 0x56545a2ed45f <unknown>
#12 0x565459dc5821 <unknown>
#13 0x7f8bd682a1ca <unknown>
#14 0x7f8bd682a28b __libc_start_main
#15 0x565459d8d4ea _start

2025-06-08 21:39:30,696 - ERROR - Full error for R Programmer/ IT - Technology Architect | data science | Machine Learning:
Traceback (most recent call last):
  File "/home/runner/work/Applier-Workflow/Applier-Workflow/scripts/src/stealth_apply.py", line 149, in easy_apply
    driver.get(job_link)
  File "/opt/hostedtoolcache/Python/3.10.17/x64/lib/python3.10/site-packages/undetected_chromedriver/__init__.py", line 496, in get_wrapped
    if self.execute_script("return navigator.webdriver"):
  File "/opt/hostedtoolcache/Python/3.10.17/x64/lib/python3.10/site-packages/selenium/webdriver/remote/webdriver.py", line 544, in execute_script
    return self.execute(command, {"script": script, "args": converted_args})["value"]
  File "/opt/hostedtoolcache/Python/3.10.17/x64/lib/python3.10/site-packages/selenium/webdriver/remote/webdriver.py", line 447, in execute
    self.error_handler.check_response(response)
  File "/opt/hostedtoolcache/Python/3.10.17/x64/lib/python3.10/site-packages/selenium/webdriver/remote/errorhandler.py", line 232, in check_response
    raise exception_class(message, screen, stacktrace)
selenium.common.exceptions.InvalidSessionIdException: Message: invalid session id
Stacktrace:
#0 0x56545a35b71a <unknown>
#1 0x565459dfdef3 <unknown>
#2 0x565459e40f0f <unknown>
#3 0x565459e752a6 <unknown>
#4 0x565459e6fbe7 <unknown>
#5 0x565459e6ed25 <unknown>
#6 0x565459dc7a88 <unknown>
#7 0x56545a3208cb <unknown>
#8 0x56545a3247ca <unknown>
#9 0x56545a308622 <unknown>
#10 0x56545a325354 <unknown>
#11 0x56545a2ed45f <unknown>
#12 0x565459dc5821 <unknown>
#13 0x7f8bd682a1ca <unknown>
#14 0x7f8bd682a28b __libc_start_main
#15 0x565459d8d4ea _start

2025-06-08 21:39:40,547 - INFO - 🎯 [73/84] Applying to: Senior Machine Learning Engineer / Hybrid in North County San Diego / NLP
2025-06-08 21:39:40,555 - ERROR -    ❌ Application failed: Message: invalid session id
Stacktrace:
#0 0x56545a35b71a <unknown>
#1 0x565459dfdef3 <unknown>
#2 0x565459e40f0f <unknown>
#3 0x565459e752a6 <unknown>
#4 0x565459e6fbe7 <unknown>
#5 0x565459e6ed25 <unknown>
#6 0x565459dc7a88 <unknown>
#7 0x56545a3208cb <unknown>
#8 0x56545a3247ca <unknown>
#9 0x56545a308622 <unknown>
#10 0x56545a325354 <unknown>
#11 0x56545a2ed45f <unknown>
#12 0x565459dc5821 <unknown>
#13 0x7f8bd682a1ca <unknown>
#14 0x7f8bd682a28b __libc_start_main
#15 0x565459d8d4ea _start

2025-06-08 21:39:40,555 - ERROR - Full error for Senior Machine Learning Engineer / Hybrid in North County San Diego / NLP:
Traceback (most recent call last):
  File "/home/runner/work/Applier-Workflow/Applier-Workflow/scripts/src/stealth_apply.py", line 149, in easy_apply
    driver.get(job_link)
  File "/opt/hostedtoolcache/Python/3.10.17/x64/lib/python3.10/site-packages/undetected_chromedriver/__init__.py", line 496, in get_wrapped
    if self.execute_script("return navigator.webdriver"):
  File "/opt/hostedtoolcache/Python/3.10.17/x64/lib/python3.10/site-packages/selenium/webdriver/remote/webdriver.py", line 544, in execute_script
    return self.execute(command, {"script": script, "args": converted_args})["value"]
  File "/opt/hostedtoolcache/Python/3.10.17/x64/lib/python3.10/site-packages/selenium/webdriver/remote/webdriver.py", line 447, in execute
    self.error_handler.check_response(response)
  File "/opt/hostedtoolcache/Python/3.10.17/x64/lib/python3.10/site-packages/selenium/webdriver/remote/errorhandler.py", line 232, in check_response
    raise exception_class(message, screen, stacktrace)
selenium.common.exceptions.InvalidSessionIdException: Message: invalid session id
Stacktrace:
#0 0x56545a35b71a <unknown>
#1 0x565459dfdef3 <unknown>
#2 0x565459e40f0f <unknown>
#3 0x565459e752a6 <unknown>
#4 0x565459e6fbe7 <unknown>
#5 0x565459e6ed25 <unknown>
#6 0x565459dc7a88 <unknown>
#7 0x56545a3208cb <unknown>
#8 0x56545a3247ca <unknown>
#9 0x56545a308622 <unknown>
#10 0x56545a325354 <unknown>
#11 0x56545a2ed45f <unknown>
#12 0x565459dc5821 <unknown>
#13 0x7f8bd682a1ca <unknown>
#14 0x7f8bd682a28b __libc_start_main
#15 0x565459d8d4ea _start

2025-06-08 21:39:50,659 - INFO - 🎯 [74/84] Applying to: Lead/Senior Full Stack Engineer (Node & React) with AI/ML
2025-06-08 21:39:50,666 - ERROR -    ❌ Application failed: Message: invalid session id
Stacktrace:
#0 0x56545a35b71a <unknown>
#1 0x565459dfdef3 <unknown>
#2 0x565459e40f0f <unknown>
#3 0x565459e752a6 <unknown>
#4 0x565459e6fbe7 <unknown>
#5 0x565459e6ed25 <unknown>
#6 0x565459dc7a88 <unknown>
#7 0x56545a3208cb <unknown>
#8 0x56545a3247ca <unknown>
#9 0x56545a308622 <unknown>
#10 0x56545a325354 <unknown>
#11 0x56545a2ed45f <unknown>
#12 0x565459dc5821 <unknown>
#13 0x7f8bd682a1ca <unknown>
#14 0x7f8bd682a28b __libc_start_main
#15 0x565459d8d4ea _start

2025-06-08 21:39:50,666 - ERROR - Full error for Lead/Senior Full Stack Engineer (Node & React) with AI/ML:
Traceback (most recent call last):
  File "/home/runner/work/Applier-Workflow/Applier-Workflow/scripts/src/stealth_apply.py", line 149, in easy_apply
    driver.get(job_link)
  File "/opt/hostedtoolcache/Python/3.10.17/x64/lib/python3.10/site-packages/undetected_chromedriver/__init__.py", line 496, in get_wrapped
    if self.execute_script("return navigator.webdriver"):
  File "/opt/hostedtoolcache/Python/3.10.17/x64/lib/python3.10/site-packages/selenium/webdriver/remote/webdriver.py", line 544, in execute_script
    return self.execute(command, {"script": script, "args": converted_args})["value"]
  File "/opt/hostedtoolcache/Python/3.10.17/x64/lib/python3.10/site-packages/selenium/webdriver/remote/webdriver.py", line 447, in execute
    self.error_handler.check_response(response)
  File "/opt/hostedtoolcache/Python/3.10.17/x64/lib/python3.10/site-packages/selenium/webdriver/remote/errorhandler.py", line 232, in check_response
    raise exception_class(message, screen, stacktrace)
selenium.common.exceptions.InvalidSessionIdException: Message: invalid session id
Stacktrace:
#0 0x56545a35b71a <unknown>
#1 0x565459dfdef3 <unknown>
#2 0x565459e40f0f <unknown>
#3 0x565459e752a6 <unknown>
#4 0x565459e6fbe7 <unknown>
#5 0x565459e6ed25 <unknown>
#6 0x565459dc7a88 <unknown>
#7 0x56545a3208cb <unknown>
#8 0x56545a3247ca <unknown>
#9 0x56545a308622 <unknown>
#10 0x56545a325354 <unknown>
#11 0x56545a2ed45f <unknown>
#12 0x565459dc5821 <unknown>
#13 0x7f8bd682a1ca <unknown>
#14 0x7f8bd682a28b __libc_start_main
#15 0x565459d8d4ea _start

2025-06-08 21:40:00,224 - INFO - 🎯 [75/84] Applying to: ML Engineer (LLMs, Go)
2025-06-08 21:40:00,231 - ERROR -    ❌ Application failed: Message: invalid session id
Stacktrace:
#0 0x56545a35b71a <unknown>
#1 0x565459dfdef3 <unknown>
#2 0x565459e40f0f <unknown>
#3 0x565459e752a6 <unknown>
#4 0x565459e6fbe7 <unknown>
#5 0x565459e6ed25 <unknown>
#6 0x565459dc7a88 <unknown>
#7 0x56545a3208cb <unknown>
#8 0x56545a3247ca <unknown>
#9 0x56545a308622 <unknown>
#10 0x56545a325354 <unknown>
#11 0x56545a2ed45f <unknown>
#12 0x565459dc5821 <unknown>
#13 0x7f8bd682a1ca <unknown>
#14 0x7f8bd682a28b __libc_start_main
#15 0x565459d8d4ea _start

2025-06-08 21:40:00,231 - ERROR - Full error for ML Engineer (LLMs, Go):
Traceback (most recent call last):
  File "/home/runner/work/Applier-Workflow/Applier-Workflow/scripts/src/stealth_apply.py", line 149, in easy_apply
    driver.get(job_link)
  File "/opt/hostedtoolcache/Python/3.10.17/x64/lib/python3.10/site-packages/undetected_chromedriver/__init__.py", line 496, in get_wrapped
    if self.execute_script("return navigator.webdriver"):
  File "/opt/hostedtoolcache/Python/3.10.17/x64/lib/python3.10/site-packages/selenium/webdriver/remote/webdriver.py", line 544, in execute_script
    return self.execute(command, {"script": script, "args": converted_args})["value"]
  File "/opt/hostedtoolcache/Python/3.10.17/x64/lib/python3.10/site-packages/selenium/webdriver/remote/webdriver.py", line 447, in execute
    self.error_handler.check_response(response)
  File "/opt/hostedtoolcache/Python/3.10.17/x64/lib/python3.10/site-packages/selenium/webdriver/remote/errorhandler.py", line 232, in check_response
    raise exception_class(message, screen, stacktrace)
selenium.common.exceptions.InvalidSessionIdException: Message: invalid session id
Stacktrace:
#0 0x56545a35b71a <unknown>
#1 0x565459dfdef3 <unknown>
#2 0x565459e40f0f <unknown>
#3 0x565459e752a6 <unknown>
#4 0x565459e6fbe7 <unknown>
#5 0x565459e6ed25 <unknown>
#6 0x565459dc7a88 <unknown>
#7 0x56545a3208cb <unknown>
#8 0x56545a3247ca <unknown>
#9 0x56545a308622 <unknown>
#10 0x56545a325354 <unknown>
#11 0x56545a2ed45f <unknown>
#12 0x565459dc5821 <unknown>
#13 0x7f8bd682a1ca <unknown>
#14 0x7f8bd682a28b __libc_start_main
#15 0x565459d8d4ea _start

2025-06-08 21:40:11,650 - INFO - 🎯 [76/84] Applying to: GenAI Architect
2025-06-08 21:40:11,658 - ERROR -    ❌ Application failed: Message: invalid session id
Stacktrace:
#0 0x56545a35b71a <unknown>
#1 0x565459dfdef3 <unknown>
#2 0x565459e40f0f <unknown>
#3 0x565459e752a6 <unknown>
#4 0x565459e6fbe7 <unknown>
#5 0x565459e6ed25 <unknown>
#6 0x565459dc7a88 <unknown>
#7 0x56545a3208cb <unknown>
#8 0x56545a3247ca <unknown>
#9 0x56545a308622 <unknown>
#10 0x56545a325354 <unknown>
#11 0x56545a2ed45f <unknown>
#12 0x565459dc5821 <unknown>
#13 0x7f8bd682a1ca <unknown>
#14 0x7f8bd682a28b __libc_start_main
#15 0x565459d8d4ea _start

2025-06-08 21:40:11,658 - ERROR - Full error for GenAI Architect:
Traceback (most recent call last):
  File "/home/runner/work/Applier-Workflow/Applier-Workflow/scripts/src/stealth_apply.py", line 149, in easy_apply
    driver.get(job_link)
  File "/opt/hostedtoolcache/Python/3.10.17/x64/lib/python3.10/site-packages/undetected_chromedriver/__init__.py", line 496, in get_wrapped
    if self.execute_script("return navigator.webdriver"):
  File "/opt/hostedtoolcache/Python/3.10.17/x64/lib/python3.10/site-packages/selenium/webdriver/remote/webdriver.py", line 544, in execute_script
    return self.execute(command, {"script": script, "args": converted_args})["value"]
  File "/opt/hostedtoolcache/Python/3.10.17/x64/lib/python3.10/site-packages/selenium/webdriver/remote/webdriver.py", line 447, in execute
    self.error_handler.check_response(response)
  File "/opt/hostedtoolcache/Python/3.10.17/x64/lib/python3.10/site-packages/selenium/webdriver/remote/errorhandler.py", line 232, in check_response
    raise exception_class(message, screen, stacktrace)
selenium.common.exceptions.InvalidSessionIdException: Message: invalid session id
Stacktrace:
#0 0x56545a35b71a <unknown>
#1 0x565459dfdef3 <unknown>
#2 0x565459e40f0f <unknown>
#3 0x565459e752a6 <unknown>
#4 0x565459e6fbe7 <unknown>
#5 0x565459e6ed25 <unknown>
#6 0x565459dc7a88 <unknown>
#7 0x56545a3208cb <unknown>
#8 0x56545a3247ca <unknown>
#9 0x56545a308622 <unknown>
#10 0x56545a325354 <unknown>
#11 0x56545a2ed45f <unknown>
#12 0x565459dc5821 <unknown>
#13 0x7f8bd682a1ca <unknown>
#14 0x7f8bd682a28b __libc_start_main
#15 0x565459d8d4ea _start

2025-06-08 21:40:20,808 - INFO - 🎯 [77/84] Applying to: Fulltime opportunity - GenAI/ML Engineer - Photon - Jersey City, NJ
2025-06-08 21:40:20,815 - ERROR -    ❌ Application failed: Message: invalid session id
Stacktrace:
#0 0x56545a35b71a <unknown>
#1 0x565459dfdef3 <unknown>
#2 0x565459e40f0f <unknown>
#3 0x565459e752a6 <unknown>
#4 0x565459e6fbe7 <unknown>
#5 0x565459e6ed25 <unknown>
#6 0x565459dc7a88 <unknown>
#7 0x56545a3208cb <unknown>
#8 0x56545a3247ca <unknown>
#9 0x56545a308622 <unknown>
#10 0x56545a325354 <unknown>
#11 0x56545a2ed45f <unknown>
#12 0x565459dc5821 <unknown>
#13 0x7f8bd682a1ca <unknown>
#14 0x7f8bd682a28b __libc_start_main
#15 0x565459d8d4ea _start

2025-06-08 21:40:20,816 - ERROR - Full error for Fulltime opportunity - GenAI/ML Engineer - Photon - Jersey City, NJ:
Traceback (most recent call last):
  File "/home/runner/work/Applier-Workflow/Applier-Workflow/scripts/src/stealth_apply.py", line 149, in easy_apply
    driver.get(job_link)
  File "/opt/hostedtoolcache/Python/3.10.17/x64/lib/python3.10/site-packages/undetected_chromedriver/__init__.py", line 496, in get_wrapped
    if self.execute_script("return navigator.webdriver"):
  File "/opt/hostedtoolcache/Python/3.10.17/x64/lib/python3.10/site-packages/selenium/webdriver/remote/webdriver.py", line 544, in execute_script
    return self.execute(command, {"script": script, "args": converted_args})["value"]
  File "/opt/hostedtoolcache/Python/3.10.17/x64/lib/python3.10/site-packages/selenium/webdriver/remote/webdriver.py", line 447, in execute
    self.error_handler.check_response(response)
  File "/opt/hostedtoolcache/Python/3.10.17/x64/lib/python3.10/site-packages/selenium/webdriver/remote/errorhandler.py", line 232, in check_response
    raise exception_class(message, screen, stacktrace)
selenium.common.exceptions.InvalidSessionIdException: Message: invalid session id
Stacktrace:
#0 0x56545a35b71a <unknown>
#1 0x565459dfdef3 <unknown>
#2 0x565459e40f0f <unknown>
#3 0x565459e752a6 <unknown>
#4 0x565459e6fbe7 <unknown>
#5 0x565459e6ed25 <unknown>
#6 0x565459dc7a88 <unknown>
#7 0x56545a3208cb <unknown>
#8 0x56545a3247ca <unknown>
#9 0x56545a308622 <unknown>
#10 0x56545a325354 <unknown>
#11 0x56545a2ed45f <unknown>
#12 0x565459dc5821 <unknown>
#13 0x7f8bd682a1ca <unknown>
#14 0x7f8bd682a28b __libc_start_main
#15 0x565459d8d4ea _start

2025-06-08 21:40:28,266 - INFO - 🎯 [78/84] Applying to: Gen AI Architect
2025-06-08 21:40:28,273 - ERROR -    ❌ Application failed: Message: invalid session id
Stacktrace:
#0 0x56545a35b71a <unknown>
#1 0x565459dfdef3 <unknown>
#2 0x565459e40f0f <unknown>
#3 0x565459e752a6 <unknown>
#4 0x565459e6fbe7 <unknown>
#5 0x565459e6ed25 <unknown>
#6 0x565459dc7a88 <unknown>
#7 0x56545a3208cb <unknown>
#8 0x56545a3247ca <unknown>
#9 0x56545a308622 <unknown>
#10 0x56545a325354 <unknown>
#11 0x56545a2ed45f <unknown>
#12 0x565459dc5821 <unknown>
#13 0x7f8bd682a1ca <unknown>
#14 0x7f8bd682a28b __libc_start_main
#15 0x565459d8d4ea _start

2025-06-08 21:40:28,273 - ERROR - Full error for Gen AI Architect:
Traceback (most recent call last):
  File "/home/runner/work/Applier-Workflow/Applier-Workflow/scripts/src/stealth_apply.py", line 149, in easy_apply
    driver.get(job_link)
  File "/opt/hostedtoolcache/Python/3.10.17/x64/lib/python3.10/site-packages/undetected_chromedriver/__init__.py", line 496, in get_wrapped
    if self.execute_script("return navigator.webdriver"):
  File "/opt/hostedtoolcache/Python/3.10.17/x64/lib/python3.10/site-packages/selenium/webdriver/remote/webdriver.py", line 544, in execute_script
    return self.execute(command, {"script": script, "args": converted_args})["value"]
  File "/opt/hostedtoolcache/Python/3.10.17/x64/lib/python3.10/site-packages/selenium/webdriver/remote/webdriver.py", line 447, in execute
    self.error_handler.check_response(response)
  File "/opt/hostedtoolcache/Python/3.10.17/x64/lib/python3.10/site-packages/selenium/webdriver/remote/errorhandler.py", line 232, in check_response
    raise exception_class(message, screen, stacktrace)
selenium.common.exceptions.InvalidSessionIdException: Message: invalid session id
Stacktrace:
#0 0x56545a35b71a <unknown>
#1 0x565459dfdef3 <unknown>
#2 0x565459e40f0f <unknown>
#3 0x565459e752a6 <unknown>
#4 0x565459e6fbe7 <unknown>
#5 0x565459e6ed25 <unknown>
#6 0x565459dc7a88 <unknown>
#7 0x56545a3208cb <unknown>
#8 0x56545a3247ca <unknown>
#9 0x56545a308622 <unknown>
#10 0x56545a325354 <unknown>
#11 0x56545a2ed45f <unknown>
#12 0x565459dc5821 <unknown>
#13 0x7f8bd682a1ca <unknown>
#14 0x7f8bd682a28b __libc_start_main
#15 0x565459d8d4ea _start

2025-06-08 21:40:34,214 - INFO - 🎯 [79/84] Applying to: Google Cloud Platform MLOPs & Vertex AI Specialist(L6)
2025-06-08 21:40:34,221 - ERROR -    ❌ Application failed: Message: invalid session id
Stacktrace:
#0 0x56545a35b71a <unknown>
#1 0x565459dfdef3 <unknown>
#2 0x565459e40f0f <unknown>
#3 0x565459e752a6 <unknown>
#4 0x565459e6fbe7 <unknown>
#5 0x565459e6ed25 <unknown>
#6 0x565459dc7a88 <unknown>
#7 0x56545a3208cb <unknown>
#8 0x56545a3247ca <unknown>
#9 0x56545a308622 <unknown>
#10 0x56545a325354 <unknown>
#11 0x56545a2ed45f <unknown>
#12 0x565459dc5821 <unknown>
#13 0x7f8bd682a1ca <unknown>
#14 0x7f8bd682a28b __libc_start_main
#15 0x565459d8d4ea _start

2025-06-08 21:40:34,221 - ERROR - Full error for Google Cloud Platform MLOPs & Vertex AI Specialist(L6):
Traceback (most recent call last):
  File "/home/runner/work/Applier-Workflow/Applier-Workflow/scripts/src/stealth_apply.py", line 149, in easy_apply
    driver.get(job_link)
  File "/opt/hostedtoolcache/Python/3.10.17/x64/lib/python3.10/site-packages/undetected_chromedriver/__init__.py", line 496, in get_wrapped
    if self.execute_script("return navigator.webdriver"):
  File "/opt/hostedtoolcache/Python/3.10.17/x64/lib/python3.10/site-packages/selenium/webdriver/remote/webdriver.py", line 544, in execute_script
    return self.execute(command, {"script": script, "args": converted_args})["value"]
  File "/opt/hostedtoolcache/Python/3.10.17/x64/lib/python3.10/site-packages/selenium/webdriver/remote/webdriver.py", line 447, in execute
    self.error_handler.check_response(response)
  File "/opt/hostedtoolcache/Python/3.10.17/x64/lib/python3.10/site-packages/selenium/webdriver/remote/errorhandler.py", line 232, in check_response
    raise exception_class(message, screen, stacktrace)
selenium.common.exceptions.InvalidSessionIdException: Message: invalid session id
Stacktrace:
#0 0x56545a35b71a <unknown>
#1 0x565459dfdef3 <unknown>
#2 0x565459e40f0f <unknown>
#3 0x565459e752a6 <unknown>
#4 0x565459e6fbe7 <unknown>
#5 0x565459e6ed25 <unknown>
#6 0x565459dc7a88 <unknown>
#7 0x56545a3208cb <unknown>
#8 0x56545a3247ca <unknown>
#9 0x56545a308622 <unknown>
#10 0x56545a325354 <unknown>
#11 0x56545a2ed45f <unknown>
#12 0x565459dc5821 <unknown>
#13 0x7f8bd682a1ca <unknown>
#14 0x7f8bd682a28b __libc_start_main
#15 0x565459d8d4ea _start

2025-06-08 21:40:44,119 - INFO - 🎯 [80/84] Applying to: AI/ML Engineer @ Arlington, Texas- USA (Day 1 Onsite) _ Full Time
2025-06-08 21:40:44,126 - ERROR -    ❌ Application failed: Message: invalid session id
Stacktrace:
#0 0x56545a35b71a <unknown>
#1 0x565459dfdef3 <unknown>
#2 0x565459e40f0f <unknown>
#3 0x565459e752a6 <unknown>
#4 0x565459e6fbe7 <unknown>
#5 0x565459e6ed25 <unknown>
#6 0x565459dc7a88 <unknown>
#7 0x56545a3208cb <unknown>
#8 0x56545a3247ca <unknown>
#9 0x56545a308622 <unknown>
#10 0x56545a325354 <unknown>
#11 0x56545a2ed45f <unknown>
#12 0x565459dc5821 <unknown>
#13 0x7f8bd682a1ca <unknown>
#14 0x7f8bd682a28b __libc_start_main
#15 0x565459d8d4ea _start

2025-06-08 21:40:44,126 - ERROR - Full error for AI/ML Engineer @ Arlington, Texas- USA (Day 1 Onsite) _ Full Time:
Traceback (most recent call last):
  File "/home/runner/work/Applier-Workflow/Applier-Workflow/scripts/src/stealth_apply.py", line 149, in easy_apply
    driver.get(job_link)
  File "/opt/hostedtoolcache/Python/3.10.17/x64/lib/python3.10/site-packages/undetected_chromedriver/__init__.py", line 496, in get_wrapped
    if self.execute_script("return navigator.webdriver"):
  File "/opt/hostedtoolcache/Python/3.10.17/x64/lib/python3.10/site-packages/selenium/webdriver/remote/webdriver.py", line 544, in execute_script
    return self.execute(command, {"script": script, "args": converted_args})["value"]
  File "/opt/hostedtoolcache/Python/3.10.17/x64/lib/python3.10/site-packages/selenium/webdriver/remote/webdriver.py", line 447, in execute
    self.error_handler.check_response(response)
  File "/opt/hostedtoolcache/Python/3.10.17/x64/lib/python3.10/site-packages/selenium/webdriver/remote/errorhandler.py", line 232, in check_response
    raise exception_class(message, screen, stacktrace)
selenium.common.exceptions.InvalidSessionIdException: Message: invalid session id
Stacktrace:
#0 0x56545a35b71a <unknown>
#1 0x565459dfdef3 <unknown>
#2 0x565459e40f0f <unknown>
#3 0x565459e752a6 <unknown>
#4 0x565459e6fbe7 <unknown>
#5 0x565459e6ed25 <unknown>
#6 0x565459dc7a88 <unknown>
#7 0x56545a3208cb <unknown>
#8 0x56545a3247ca <unknown>
#9 0x56545a308622 <unknown>
#10 0x56545a325354 <unknown>
#11 0x56545a2ed45f <unknown>
#12 0x565459dc5821 <unknown>
#13 0x7f8bd682a1ca <unknown>
#14 0x7f8bd682a28b __libc_start_main
#15 0x565459d8d4ea _start

2025-06-08 21:40:52,790 - INFO - 🎯 [81/84] Applying to: AI/ML Platform Engineer
2025-06-08 21:40:52,797 - ERROR -    ❌ Application failed: Message: invalid session id
Stacktrace:
#0 0x56545a35b71a <unknown>
#1 0x565459dfdef3 <unknown>
#2 0x565459e40f0f <unknown>
#3 0x565459e752a6 <unknown>
#4 0x565459e6fbe7 <unknown>
#5 0x565459e6ed25 <unknown>
#6 0x565459dc7a88 <unknown>
#7 0x56545a3208cb <unknown>
#8 0x56545a3247ca <unknown>
#9 0x56545a308622 <unknown>
#10 0x56545a325354 <unknown>
#11 0x56545a2ed45f <unknown>
#12 0x565459dc5821 <unknown>
#13 0x7f8bd682a1ca <unknown>
#14 0x7f8bd682a28b __libc_start_main
#15 0x565459d8d4ea _start

2025-06-08 21:40:52,797 - ERROR - Full error for AI/ML Platform Engineer:
Traceback (most recent call last):
  File "/home/runner/work/Applier-Workflow/Applier-Workflow/scripts/src/stealth_apply.py", line 149, in easy_apply
    driver.get(job_link)
  File "/opt/hostedtoolcache/Python/3.10.17/x64/lib/python3.10/site-packages/undetected_chromedriver/__init__.py", line 496, in get_wrapped
    if self.execute_script("return navigator.webdriver"):
  File "/opt/hostedtoolcache/Python/3.10.17/x64/lib/python3.10/site-packages/selenium/webdriver/remote/webdriver.py", line 544, in execute_script
    return self.execute(command, {"script": script, "args": converted_args})["value"]
  File "/opt/hostedtoolcache/Python/3.10.17/x64/lib/python3.10/site-packages/selenium/webdriver/remote/webdriver.py", line 447, in execute
    self.error_handler.check_response(response)
  File "/opt/hostedtoolcache/Python/3.10.17/x64/lib/python3.10/site-packages/selenium/webdriver/remote/errorhandler.py", line 232, in check_response
    raise exception_class(message, screen, stacktrace)
selenium.common.exceptions.InvalidSessionIdException: Message: invalid session id
Stacktrace:
#0 0x56545a35b71a <unknown>
#1 0x565459dfdef3 <unknown>
#2 0x565459e40f0f <unknown>
#3 0x565459e752a6 <unknown>
#4 0x565459e6fbe7 <unknown>
#5 0x565459e6ed25 <unknown>
#6 0x565459dc7a88 <unknown>
#7 0x56545a3208cb <unknown>
#8 0x56545a3247ca <unknown>
#9 0x56545a308622 <unknown>
#10 0x56545a325354 <unknown>
#11 0x56545a2ed45f <unknown>
#12 0x565459dc5821 <unknown>
#13 0x7f8bd682a1ca <unknown>
#14 0x7f8bd682a28b __libc_start_main
#15 0x565459d8d4ea _start

2025-06-08 21:41:02,437 - INFO - 🎯 [82/84] Applying to: Data engineer - Content Retrieval
2025-06-08 21:41:02,444 - ERROR -    ❌ Application failed: Message: invalid session id
Stacktrace:
#0 0x56545a35b71a <unknown>
#1 0x565459dfdef3 <unknown>
#2 0x565459e40f0f <unknown>
#3 0x565459e752a6 <unknown>
#4 0x565459e6fbe7 <unknown>
#5 0x565459e6ed25 <unknown>
#6 0x565459dc7a88 <unknown>
#7 0x56545a3208cb <unknown>
#8 0x56545a3247ca <unknown>
#9 0x56545a308622 <unknown>
#10 0x56545a325354 <unknown>
#11 0x56545a2ed45f <unknown>
#12 0x565459dc5821 <unknown>
#13 0x7f8bd682a1ca <unknown>
#14 0x7f8bd682a28b __libc_start_main
#15 0x565459d8d4ea _start

2025-06-08 21:41:02,444 - ERROR - Full error for Data engineer - Content Retrieval:
Traceback (most recent call last):
  File "/home/runner/work/Applier-Workflow/Applier-Workflow/scripts/src/stealth_apply.py", line 149, in easy_apply
    driver.get(job_link)
  File "/opt/hostedtoolcache/Python/3.10.17/x64/lib/python3.10/site-packages/undetected_chromedriver/__init__.py", line 496, in get_wrapped
    if self.execute_script("return navigator.webdriver"):
  File "/opt/hostedtoolcache/Python/3.10.17/x64/lib/python3.10/site-packages/selenium/webdriver/remote/webdriver.py", line 544, in execute_script
    return self.execute(command, {"script": script, "args": converted_args})["value"]
  File "/opt/hostedtoolcache/Python/3.10.17/x64/lib/python3.10/site-packages/selenium/webdriver/remote/webdriver.py", line 447, in execute
    self.error_handler.check_response(response)
  File "/opt/hostedtoolcache/Python/3.10.17/x64/lib/python3.10/site-packages/selenium/webdriver/remote/errorhandler.py", line 232, in check_response
    raise exception_class(message, screen, stacktrace)
selenium.common.exceptions.InvalidSessionIdException: Message: invalid session id
Stacktrace:
#0 0x56545a35b71a <unknown>
#1 0x565459dfdef3 <unknown>
#2 0x565459e40f0f <unknown>
#3 0x565459e752a6 <unknown>
#4 0x565459e6fbe7 <unknown>
#5 0x565459e6ed25 <unknown>
#6 0x565459dc7a88 <unknown>
#7 0x56545a3208cb <unknown>
#8 0x56545a3247ca <unknown>
#9 0x56545a308622 <unknown>
#10 0x56545a325354 <unknown>
#11 0x56545a2ed45f <unknown>
#12 0x565459dc5821 <unknown>
#13 0x7f8bd682a1ca <unknown>
#14 0x7f8bd682a28b __libc_start_main
#15 0x565459d8d4ea _start

2025-06-08 21:41:09,992 - INFO - 🎯 [83/84] Applying to: AI Engineer
2025-06-08 21:41:09,999 - ERROR -    ❌ Application failed: Message: invalid session id
Stacktrace:
#0 0x56545a35b71a <unknown>
#1 0x565459dfdef3 <unknown>
#2 0x565459e40f0f <unknown>
#3 0x565459e752a6 <unknown>
#4 0x565459e6fbe7 <unknown>
#5 0x565459e6ed25 <unknown>
#6 0x565459dc7a88 <unknown>
#7 0x56545a3208cb <unknown>
#8 0x56545a3247ca <unknown>
#9 0x56545a308622 <unknown>
#10 0x56545a325354 <unknown>
#11 0x56545a2ed45f <unknown>
#12 0x565459dc5821 <unknown>
#13 0x7f8bd682a1ca <unknown>
#14 0x7f8bd682a28b __libc_start_main
#15 0x565459d8d4ea _start

2025-06-08 21:41:09,999 - ERROR - Full error for AI Engineer:
Traceback (most recent call last):
  File "/home/runner/work/Applier-Workflow/Applier-Workflow/scripts/src/stealth_apply.py", line 149, in easy_apply
    driver.get(job_link)
  File "/opt/hostedtoolcache/Python/3.10.17/x64/lib/python3.10/site-packages/undetected_chromedriver/__init__.py", line 496, in get_wrapped
    if self.execute_script("return navigator.webdriver"):
  File "/opt/hostedtoolcache/Python/3.10.17/x64/lib/python3.10/site-packages/selenium/webdriver/remote/webdriver.py", line 544, in execute_script
    return self.execute(command, {"script": script, "args": converted_args})["value"]
  File "/opt/hostedtoolcache/Python/3.10.17/x64/lib/python3.10/site-packages/selenium/webdriver/remote/webdriver.py", line 447, in execute
    self.error_handler.check_response(response)
  File "/opt/hostedtoolcache/Python/3.10.17/x64/lib/python3.10/site-packages/selenium/webdriver/remote/errorhandler.py", line 232, in check_response
    raise exception_class(message, screen, stacktrace)
selenium.common.exceptions.InvalidSessionIdException: Message: invalid session id
Stacktrace:
#0 0x56545a35b71a <unknown>
#1 0x565459dfdef3 <unknown>
#2 0x565459e40f0f <unknown>
#3 0x565459e752a6 <unknown>
#4 0x565459e6fbe7 <unknown>
#5 0x565459e6ed25 <unknown>
#6 0x565459dc7a88 <unknown>
#7 0x56545a3208cb <unknown>
#8 0x56545a3247ca <unknown>
#9 0x56545a308622 <unknown>
#10 0x56545a325354 <unknown>
#11 0x56545a2ed45f <unknown>
#12 0x565459dc5821 <unknown>
#13 0x7f8bd682a1ca <unknown>
#14 0x7f8bd682a28b __libc_start_main
#15 0x565459d8d4ea _start

2025-06-08 21:41:19,018 - INFO - 🎯 [84/84] Applying to: AI Prompt Engineer
2025-06-08 21:41:19,025 - ERROR -    ❌ Application failed: Message: invalid session id
Stacktrace:
#0 0x56545a35b71a <unknown>
#1 0x565459dfdef3 <unknown>
#2 0x565459e40f0f <unknown>
#3 0x565459e752a6 <unknown>
#4 0x565459e6fbe7 <unknown>
#5 0x565459e6ed25 <unknown>
#6 0x565459dc7a88 <unknown>
#7 0x56545a3208cb <unknown>
#8 0x56545a3247ca <unknown>
#9 0x56545a308622 <unknown>
#10 0x56545a325354 <unknown>
#11 0x56545a2ed45f <unknown>
#12 0x565459dc5821 <unknown>
#13 0x7f8bd682a1ca <unknown>
#14 0x7f8bd682a28b __libc_start_main
#15 0x565459d8d4ea _start

2025-06-08 21:41:19,025 - ERROR - Full error for AI Prompt Engineer:
Traceback (most recent call last):
  File "/home/runner/work/Applier-Workflow/Applier-Workflow/scripts/src/stealth_apply.py", line 149, in easy_apply
    driver.get(job_link)
  File "/opt/hostedtoolcache/Python/3.10.17/x64/lib/python3.10/site-packages/undetected_chromedriver/__init__.py", line 496, in get_wrapped
    if self.execute_script("return navigator.webdriver"):
  File "/opt/hostedtoolcache/Python/3.10.17/x64/lib/python3.10/site-packages/selenium/webdriver/remote/webdriver.py", line 544, in execute_script
    return self.execute(command, {"script": script, "args": converted_args})["value"]
  File "/opt/hostedtoolcache/Python/3.10.17/x64/lib/python3.10/site-packages/selenium/webdriver/remote/webdriver.py", line 447, in execute
    self.error_handler.check_response(response)
  File "/opt/hostedtoolcache/Python/3.10.17/x64/lib/python3.10/site-packages/selenium/webdriver/remote/errorhandler.py", line 232, in check_response
    raise exception_class(message, screen, stacktrace)
selenium.common.exceptions.InvalidSessionIdException: Message: invalid session id
Stacktrace:
#0 0x56545a35b71a <unknown>
#1 0x565459dfdef3 <unknown>
#2 0x565459e40f0f <unknown>
#3 0x565459e752a6 <unknown>
#4 0x565459e6fbe7 <unknown>
#5 0x565459e6ed25 <unknown>
#6 0x565459dc7a88 <unknown>
#7 0x56545a3208cb <unknown>
#8 0x56545a3247ca <unknown>
#9 0x56545a308622 <unknown>
#10 0x56545a325354 <unknown>
#11 0x56545a2ed45f <unknown>
#12 0x565459dc5821 <unknown>
#13 0x7f8bd682a1ca <unknown>
#14 0x7f8bd682a28b __libc_start_main
#15 0x565459d8d4ea _start

2025-06-08 21:41:22,022 - INFO - 📊 Processing results...
2025-06-08 21:41:22,034 - INFO - 🎉 Application run completed!
2025-06-08 21:41:22,034 - INFO -    ✅ Newly applied: 37
2025-06-08 21:41:22,034 - INFO -    ⏭️  Already applied: 0
2025-06-08 21:41:22,034 - INFO -    ❌ Failed: 47
2025-06-08 21:41:22,034 - INFO -    📊 Total processed: 84
2025-06-08 21:41:22,034 - INFO -    📁 Total jobs in CSV: 716
2025-06-08 21:41:22,034 - INFO -    💾 Updated: output/final_ml_jobs.csv
2025-06-08 21:41:22,034 - INFO - 🔧 Closing browser...
