2025-07-16 17:31:36,016 - INFO - üöÄ Starting stealth job application bot
2025-07-16 17:31:41,634 - INFO - üìÇ Loading jobs from output/final_ml_jobs.csv
2025-07-16 17:31:41,644 - INFO -    üìä Total jobs in file: 580
2025-07-16 17:31:41,647 - INFO -    üéØ Easy Apply jobs: 580
2025-07-16 17:31:41,649 - INFO -    ‚è≥ Jobs to process: 22 (status: pending)
2025-07-16 17:31:41,651 - INFO - üé≤ Will attempt 22 applications this run (target: 99)
2025-07-16 17:31:41,651 - INFO - üîë Logging into Dice...
2025-07-16 17:31:44,046 - INFO - ‚úÖ Login successful
2025-07-16 17:31:46,781 - INFO - üîÑ Starting job applications...
2025-07-16 17:31:46,782 - INFO - üéØ [1/22] Applying to: Data Engineer - LINK: https://www.dice.com/job-detail/2e522153-48af-4af1-9293-a8648c2e04cb
2025-07-16 17:33:57,084 - ERROR -    ‚ùå Cannot click first NEXT button: HTTPConnectionPool(host='localhost', port=33403): Read timed out. (read timeout=120)
2025-07-16 17:36:04,400 - INFO - üéØ [2/22] Applying to: Founding ML Engineer - LINK: https://www.dice.com/job-detail/21e801c7-b9fe-4c6c-8067-4b1fa59a4f8f
2025-07-16 17:37:12,770 - ERROR -    ‚ùå Cannot click apply button: Message: element not interactable
  (Session info: chrome=138.0.7204.100); For documentation on this error, please visit: https://www.selenium.dev/documentation/webdriver/troubleshooting/errors#elementnotinteractableexception
Stacktrace:
#0 0x5617c85bb7da <unknown>
#1 0x5617c8060133 <unknown>
#2 0x5617c80b300e <unknown>
#3 0x5617c80a60ea <unknown>
#4 0x5617c80d78b2 <unknown>
#5 0x5617c80a5a6a <unknown>
#6 0x5617c80d7a7e <unknown>
#7 0x5617c80fd71c <unknown>
#8 0x5617c80d7683 <unknown>
#9 0x5617c80a3b5b <unknown>
#10 0x5617c80a4f31 <unknown>
#11 0x5617c858072b <unknown>
#12 0x5617c8584534 <unknown>
#13 0x5617c8567229 <unknown>
#14 0x5617c85850d8 <unknown>
#15 0x5617c854b61f <unknown>
#16 0x5617c85a8dd8 <unknown>
#17 0x5617c85a8fb6 <unknown>
#18 0x5617c85baaf6 <unknown>
#19 0x7f8fade9caa4 <unknown>
#20 0x7f8fadf29c3c <unknown>

2025-07-16 17:37:22,921 - INFO - üéØ [3/22] Applying to: AI/ML Engineer (AIOps or MLOps exp) - LINK: https://www.dice.com/job-detail/b4afcc9b-a653-4389-abdb-f47f5aab535b
2025-07-16 17:37:35,708 - ERROR -    ‚ùå Cannot click apply button: Message: element not interactable
  (Session info: chrome=138.0.7204.100); For documentation on this error, please visit: https://www.selenium.dev/documentation/webdriver/troubleshooting/errors#elementnotinteractableexception
Stacktrace:
#0 0x5617c85bb7da <unknown>
#1 0x5617c8060133 <unknown>
#2 0x5617c80b300e <unknown>
#3 0x5617c80a60ea <unknown>
#4 0x5617c80d78b2 <unknown>
#5 0x5617c80a5a6a <unknown>
#6 0x5617c80d7a7e <unknown>
#7 0x5617c80fd71c <unknown>
#8 0x5617c80d7683 <unknown>
#9 0x5617c80a3b5b <unknown>
#10 0x5617c80a4f31 <unknown>
#11 0x5617c858072b <unknown>
#12 0x5617c8584534 <unknown>
#13 0x5617c8567229 <unknown>
#14 0x5617c85850d8 <unknown>
#15 0x5617c854b61f <unknown>
#16 0x5617c85a8dd8 <unknown>
#17 0x5617c85a8fb6 <unknown>
#18 0x5617c85baaf6 <unknown>
#19 0x7f8fade9caa4 <unknown>
#20 0x7f8fadf29c3c <unknown>

2025-07-16 17:37:44,893 - INFO - üéØ [4/22] Applying to: AI/ML Data Scientist - LINK: https://www.dice.com/job-detail/50cca45c-62a4-4d15-a79a-124592795167
2025-07-16 17:38:03,606 - ERROR -    ‚ùå Cannot click apply button: Message: element not interactable
  (Session info: chrome=138.0.7204.100); For documentation on this error, please visit: https://www.selenium.dev/documentation/webdriver/troubleshooting/errors#elementnotinteractableexception
Stacktrace:
#0 0x5617c85bb7da <unknown>
#1 0x5617c8060133 <unknown>
#2 0x5617c80b300e <unknown>
#3 0x5617c80a60ea <unknown>
#4 0x5617c80d78b2 <unknown>
#5 0x5617c80a5a6a <unknown>
#6 0x5617c80d7a7e <unknown>
#7 0x5617c80fd71c <unknown>
#8 0x5617c80d7683 <unknown>
#9 0x5617c80a3b5b <unknown>
#10 0x5617c80a4f31 <unknown>
#11 0x5617c858072b <unknown>
#12 0x5617c8584534 <unknown>
#13 0x5617c8567229 <unknown>
#14 0x5617c85850d8 <unknown>
#15 0x5617c854b61f <unknown>
#16 0x5617c85a8dd8 <unknown>
#17 0x5617c85a8fb6 <unknown>
#18 0x5617c85baaf6 <unknown>
#19 0x7f8fade9caa4 <unknown>
#20 0x7f8fadf29c3c <unknown>

2025-07-16 17:38:11,334 - INFO - üéØ [5/22] Applying to: AI/ML Solution Engineer - LINK: https://www.dice.com/job-detail/b718d79f-fbf5-4590-8e64-d2605e6a57dc
2025-07-16 17:38:28,627 - INFO -    ‚úÖ Successfully applied!
2025-07-16 17:40:38,769 - INFO - üéØ [6/22] Applying to: Cloud/AI/ML Architect - LINK: https://www.dice.com/job-detail/be35a89a-dd12-42a6-87b5-e502171f3bb7
2025-07-16 17:42:38,775 - ERROR -    ‚ùå Application failed: HTTPConnectionPool(host='localhost', port=33403): Read timed out. (read timeout=120)
2025-07-16 17:42:38,776 - ERROR - Full error for Cloud/AI/ML Architect:
Traceback (most recent call last):
  File "/opt/hostedtoolcache/Python/3.10.18/x64/lib/python3.10/site-packages/urllib3/connectionpool.py", line 534, in _make_request
    response = conn.getresponse()
  File "/opt/hostedtoolcache/Python/3.10.18/x64/lib/python3.10/site-packages/urllib3/connection.py", line 565, in getresponse
    httplib_response = super().getresponse()
  File "/opt/hostedtoolcache/Python/3.10.18/x64/lib/python3.10/http/client.py", line 1375, in getresponse
    response.begin()
  File "/opt/hostedtoolcache/Python/3.10.18/x64/lib/python3.10/http/client.py", line 318, in begin
    version, status, reason = self._read_status()
  File "/opt/hostedtoolcache/Python/3.10.18/x64/lib/python3.10/http/client.py", line 279, in _read_status
    line = str(self.fp.readline(_MAXLINE + 1), "iso-8859-1")
  File "/opt/hostedtoolcache/Python/3.10.18/x64/lib/python3.10/socket.py", line 717, in readinto
    return self._sock.recv_into(b)
TimeoutError: timed out

The above exception was the direct cause of the following exception:

Traceback (most recent call last):
  File "/home/runner/work/Applier-Workflow/Applier-Workflow/scripts/src/stealth_apply.py", line 145, in easy_apply
    driver.get(job_link)
  File "/opt/hostedtoolcache/Python/3.10.18/x64/lib/python3.10/site-packages/undetected_chromedriver/__init__.py", line 496, in get_wrapped
    if self.execute_script("return navigator.webdriver"):
  File "/opt/hostedtoolcache/Python/3.10.18/x64/lib/python3.10/site-packages/selenium/webdriver/remote/webdriver.py", line 551, in execute_script
    return self.execute(command, {"script": script, "args": converted_args})["value"]
  File "/opt/hostedtoolcache/Python/3.10.18/x64/lib/python3.10/site-packages/selenium/webdriver/remote/webdriver.py", line 451, in execute
    response = cast(RemoteConnection, self.command_executor).execute(driver_command, params)
  File "/opt/hostedtoolcache/Python/3.10.18/x64/lib/python3.10/site-packages/selenium/webdriver/remote/remote_connection.py", line 404, in execute
    return self._request(command_info[0], url, body=data)
  File "/opt/hostedtoolcache/Python/3.10.18/x64/lib/python3.10/site-packages/selenium/webdriver/remote/remote_connection.py", line 428, in _request
    response = self._conn.request(method, url, body=body, headers=headers, timeout=self._client_config.timeout)
  File "/opt/hostedtoolcache/Python/3.10.18/x64/lib/python3.10/site-packages/urllib3/_request_methods.py", line 143, in request
    return self.request_encode_body(
  File "/opt/hostedtoolcache/Python/3.10.18/x64/lib/python3.10/site-packages/urllib3/_request_methods.py", line 278, in request_encode_body
    return self.urlopen(method, url, **extra_kw)
  File "/opt/hostedtoolcache/Python/3.10.18/x64/lib/python3.10/site-packages/urllib3/poolmanager.py", line 459, in urlopen
    response = conn.urlopen(method, u.request_uri, **kw)
  File "/opt/hostedtoolcache/Python/3.10.18/x64/lib/python3.10/site-packages/urllib3/connectionpool.py", line 841, in urlopen
    retries = retries.increment(
  File "/opt/hostedtoolcache/Python/3.10.18/x64/lib/python3.10/site-packages/urllib3/util/retry.py", line 474, in increment
    raise reraise(type(error), error, _stacktrace)
  File "/opt/hostedtoolcache/Python/3.10.18/x64/lib/python3.10/site-packages/urllib3/util/util.py", line 39, in reraise
    raise value
  File "/opt/hostedtoolcache/Python/3.10.18/x64/lib/python3.10/site-packages/urllib3/connectionpool.py", line 787, in urlopen
    response = self._make_request(
  File "/opt/hostedtoolcache/Python/3.10.18/x64/lib/python3.10/site-packages/urllib3/connectionpool.py", line 536, in _make_request
    self._raise_timeout(err=e, url=url, timeout_value=read_timeout)
  File "/opt/hostedtoolcache/Python/3.10.18/x64/lib/python3.10/site-packages/urllib3/connectionpool.py", line 367, in _raise_timeout
    raise ReadTimeoutError(
urllib3.exceptions.ReadTimeoutError: HTTPConnectionPool(host='localhost', port=33403): Read timed out. (read timeout=120)
2025-07-16 17:43:39,898 - INFO - üéØ [7/22] Applying to: AI/ML Specialist (Mid) - LINK: https://www.dice.com/job-detail/c47ce698-cf32-4a79-b6fb-a17d30203806
2025-07-16 17:43:59,058 - INFO -    ‚úÖ Successfully applied!
2025-07-16 17:46:08,687 - INFO - üéØ [8/22] Applying to: Senior AI/ML Specialist - LINK: https://www.dice.com/job-detail/b698a2dc-ac89-443e-8246-f67697ddffcf
2025-07-16 17:48:08,720 - ERROR -    ‚ùå Application failed: HTTPConnectionPool(host='localhost', port=33403): Read timed out. (read timeout=120)
2025-07-16 17:48:08,721 - ERROR - Full error for Senior AI/ML Specialist:
Traceback (most recent call last):
  File "/opt/hostedtoolcache/Python/3.10.18/x64/lib/python3.10/site-packages/urllib3/connectionpool.py", line 534, in _make_request
    response = conn.getresponse()
  File "/opt/hostedtoolcache/Python/3.10.18/x64/lib/python3.10/site-packages/urllib3/connection.py", line 565, in getresponse
    httplib_response = super().getresponse()
  File "/opt/hostedtoolcache/Python/3.10.18/x64/lib/python3.10/http/client.py", line 1375, in getresponse
    response.begin()
  File "/opt/hostedtoolcache/Python/3.10.18/x64/lib/python3.10/http/client.py", line 318, in begin
    version, status, reason = self._read_status()
  File "/opt/hostedtoolcache/Python/3.10.18/x64/lib/python3.10/http/client.py", line 279, in _read_status
    line = str(self.fp.readline(_MAXLINE + 1), "iso-8859-1")
  File "/opt/hostedtoolcache/Python/3.10.18/x64/lib/python3.10/socket.py", line 717, in readinto
    return self._sock.recv_into(b)
TimeoutError: timed out

The above exception was the direct cause of the following exception:

Traceback (most recent call last):
  File "/home/runner/work/Applier-Workflow/Applier-Workflow/scripts/src/stealth_apply.py", line 145, in easy_apply
    driver.get(job_link)
  File "/opt/hostedtoolcache/Python/3.10.18/x64/lib/python3.10/site-packages/undetected_chromedriver/__init__.py", line 496, in get_wrapped
    if self.execute_script("return navigator.webdriver"):
  File "/opt/hostedtoolcache/Python/3.10.18/x64/lib/python3.10/site-packages/selenium/webdriver/remote/webdriver.py", line 551, in execute_script
    return self.execute(command, {"script": script, "args": converted_args})["value"]
  File "/opt/hostedtoolcache/Python/3.10.18/x64/lib/python3.10/site-packages/selenium/webdriver/remote/webdriver.py", line 451, in execute
    response = cast(RemoteConnection, self.command_executor).execute(driver_command, params)
  File "/opt/hostedtoolcache/Python/3.10.18/x64/lib/python3.10/site-packages/selenium/webdriver/remote/remote_connection.py", line 404, in execute
    return self._request(command_info[0], url, body=data)
  File "/opt/hostedtoolcache/Python/3.10.18/x64/lib/python3.10/site-packages/selenium/webdriver/remote/remote_connection.py", line 428, in _request
    response = self._conn.request(method, url, body=body, headers=headers, timeout=self._client_config.timeout)
  File "/opt/hostedtoolcache/Python/3.10.18/x64/lib/python3.10/site-packages/urllib3/_request_methods.py", line 143, in request
    return self.request_encode_body(
  File "/opt/hostedtoolcache/Python/3.10.18/x64/lib/python3.10/site-packages/urllib3/_request_methods.py", line 278, in request_encode_body
    return self.urlopen(method, url, **extra_kw)
  File "/opt/hostedtoolcache/Python/3.10.18/x64/lib/python3.10/site-packages/urllib3/poolmanager.py", line 459, in urlopen
    response = conn.urlopen(method, u.request_uri, **kw)
  File "/opt/hostedtoolcache/Python/3.10.18/x64/lib/python3.10/site-packages/urllib3/connectionpool.py", line 841, in urlopen
    retries = retries.increment(
  File "/opt/hostedtoolcache/Python/3.10.18/x64/lib/python3.10/site-packages/urllib3/util/retry.py", line 474, in increment
    raise reraise(type(error), error, _stacktrace)
  File "/opt/hostedtoolcache/Python/3.10.18/x64/lib/python3.10/site-packages/urllib3/util/util.py", line 39, in reraise
    raise value
  File "/opt/hostedtoolcache/Python/3.10.18/x64/lib/python3.10/site-packages/urllib3/connectionpool.py", line 787, in urlopen
    response = self._make_request(
  File "/opt/hostedtoolcache/Python/3.10.18/x64/lib/python3.10/site-packages/urllib3/connectionpool.py", line 536, in _make_request
    self._raise_timeout(err=e, url=url, timeout_value=read_timeout)
  File "/opt/hostedtoolcache/Python/3.10.18/x64/lib/python3.10/site-packages/urllib3/connectionpool.py", line 367, in _raise_timeout
    raise ReadTimeoutError(
urllib3.exceptions.ReadTimeoutError: HTTPConnectionPool(host='localhost', port=33403): Read timed out. (read timeout=120)
2025-07-16 17:49:09,833 - INFO - üéØ [9/22] Applying to: Enterprise Architect (TOGAF, AI/ML) - LINK: https://www.dice.com/job-detail/1836557f-9e84-48f8-a367-4cf2a5fc8e40
2025-07-16 17:51:22,246 - ERROR -    ‚ùå Cannot click first NEXT button: HTTPConnectionPool(host='localhost', port=33403): Read timed out. (read timeout=120)
2025-07-16 17:53:28,951 - INFO - üéØ [10/22] Applying to: Data Scientist AI/ML - Jersey City, NJ - LINK: https://www.dice.com/job-detail/767a65d9-c47b-4bcc-b2e5-597b1f2eff81
2025-07-16 17:54:40,521 - ERROR -    ‚ùå Cannot click apply button: Message: element not interactable
  (Session info: chrome=138.0.7204.100); For documentation on this error, please visit: https://www.selenium.dev/documentation/webdriver/troubleshooting/errors#elementnotinteractableexception
Stacktrace:
#0 0x5617c85bb7da <unknown>
#1 0x5617c8060133 <unknown>
#2 0x5617c80b300e <unknown>
#3 0x5617c80a60ea <unknown>
#4 0x5617c80d78b2 <unknown>
#5 0x5617c80a5a6a <unknown>
#6 0x5617c80d7a7e <unknown>
#7 0x5617c80fd71c <unknown>
#8 0x5617c80d7683 <unknown>
#9 0x5617c80a3b5b <unknown>
#10 0x5617c80a4f31 <unknown>
#11 0x5617c858072b <unknown>
#12 0x5617c8584534 <unknown>
#13 0x5617c8567229 <unknown>
#14 0x5617c85850d8 <unknown>
#15 0x5617c854b61f <unknown>
#16 0x5617c85a8dd8 <unknown>
#17 0x5617c85a8fb6 <unknown>
#18 0x5617c85baaf6 <unknown>
#19 0x7f8fade9caa4 <unknown>
#20 0x7f8fadf29c3c <unknown>

2025-07-16 17:54:50,476 - INFO - üéØ [11/22] Applying to: Machine Learning Engineer - LINK: https://www.dice.com/job-detail/adece39e-1b9e-4601-bf92-eadf58fe91a3
2025-07-16 17:55:06,350 - ERROR -    ‚ùå Cannot click apply button: Message: element not interactable
  (Session info: chrome=138.0.7204.100); For documentation on this error, please visit: https://www.selenium.dev/documentation/webdriver/troubleshooting/errors#elementnotinteractableexception
Stacktrace:
#0 0x5617c85bb7da <unknown>
#1 0x5617c8060133 <unknown>
#2 0x5617c80b300e <unknown>
#3 0x5617c80a60ea <unknown>
#4 0x5617c80d78b2 <unknown>
#5 0x5617c80a5a6a <unknown>
#6 0x5617c80d7a7e <unknown>
#7 0x5617c80fd71c <unknown>
#8 0x5617c80d7683 <unknown>
#9 0x5617c80a3b5b <unknown>
#10 0x5617c80a4f31 <unknown>
#11 0x5617c858072b <unknown>
#12 0x5617c8584534 <unknown>
#13 0x5617c8567229 <unknown>
#14 0x5617c85850d8 <unknown>
#15 0x5617c854b61f <unknown>
#16 0x5617c85a8dd8 <unknown>
#17 0x5617c85a8fb6 <unknown>
#18 0x5617c85baaf6 <unknown>
#19 0x7f8fade9caa4 <unknown>
#20 0x7f8fadf29c3c <unknown>

2025-07-16 17:55:18,184 - INFO - üéØ [12/22] Applying to: Enterprise Architect- Cloud Platforms & AI/ML - LINK: https://www.dice.com/job-detail/f975cd60-dc3e-4a52-b558-dacfdd20d893
2025-07-16 17:55:34,384 - ERROR -    ‚ùå Cannot click apply button: Message: element not interactable
  (Session info: chrome=138.0.7204.100); For documentation on this error, please visit: https://www.selenium.dev/documentation/webdriver/troubleshooting/errors#elementnotinteractableexception
Stacktrace:
#0 0x5617c85bb7da <unknown>
#1 0x5617c8060133 <unknown>
#2 0x5617c80b300e <unknown>
#3 0x5617c80a60ea <unknown>
#4 0x5617c80d78b2 <unknown>
#5 0x5617c80a5a6a <unknown>
#6 0x5617c80d7a7e <unknown>
#7 0x5617c80fd71c <unknown>
#8 0x5617c80d7683 <unknown>
#9 0x5617c80a3b5b <unknown>
#10 0x5617c80a4f31 <unknown>
#11 0x5617c858072b <unknown>
#12 0x5617c8584534 <unknown>
#13 0x5617c8567229 <unknown>
#14 0x5617c85850d8 <unknown>
#15 0x5617c854b61f <unknown>
#16 0x5617c85a8dd8 <unknown>
#17 0x5617c85a8fb6 <unknown>
#18 0x5617c85baaf6 <unknown>
#19 0x7f8fade9caa4 <unknown>
#20 0x7f8fadf29c3c <unknown>

2025-07-16 17:55:44,006 - INFO - üéØ [13/22] Applying to: Data AI Engineer - Local to Atlanta, GA - LINK: https://www.dice.com/job-detail/18aefcee-7282-4e55-9e5b-d3a8c5b347a0
2025-07-16 17:55:56,355 - ERROR -    ‚ùå Cannot click apply button: Message: element not interactable
  (Session info: chrome=138.0.7204.100); For documentation on this error, please visit: https://www.selenium.dev/documentation/webdriver/troubleshooting/errors#elementnotinteractableexception
Stacktrace:
#0 0x5617c85bb7da <unknown>
#1 0x5617c8060133 <unknown>
#2 0x5617c80b300e <unknown>
#3 0x5617c80a60ea <unknown>
#4 0x5617c80d78b2 <unknown>
#5 0x5617c80a5a6a <unknown>
#6 0x5617c80d7a7e <unknown>
#7 0x5617c80fd71c <unknown>
#8 0x5617c80d7683 <unknown>
#9 0x5617c80a3b5b <unknown>
#10 0x5617c80a4f31 <unknown>
#11 0x5617c858072b <unknown>
#12 0x5617c8584534 <unknown>
#13 0x5617c8567229 <unknown>
#14 0x5617c85850d8 <unknown>
#15 0x5617c854b61f <unknown>
#16 0x5617c85a8dd8 <unknown>
#17 0x5617c85a8fb6 <unknown>
#18 0x5617c85baaf6 <unknown>
#19 0x7f8fade9caa4 <unknown>
#20 0x7f8fadf29c3c <unknown>

2025-07-16 17:56:09,617 - INFO - üéØ [14/22] Applying to: AI/MLengineer@ Onsite (Only w2) - LINK: https://www.dice.com/job-detail/8494c53e-5980-4f9d-b68a-c8c1f41e56e5
2025-07-16 17:56:26,933 - ERROR -    ‚ùå Cannot click apply button: Message: element not interactable
  (Session info: chrome=138.0.7204.100); For documentation on this error, please visit: https://www.selenium.dev/documentation/webdriver/troubleshooting/errors#elementnotinteractableexception
Stacktrace:
#0 0x5617c85bb7da <unknown>
#1 0x5617c8060133 <unknown>
#2 0x5617c80b300e <unknown>
#3 0x5617c80a60ea <unknown>
#4 0x5617c80d78b2 <unknown>
#5 0x5617c80a5a6a <unknown>
#6 0x5617c80d7a7e <unknown>
#7 0x5617c80fd71c <unknown>
#8 0x5617c80d7683 <unknown>
#9 0x5617c80a3b5b <unknown>
#10 0x5617c80a4f31 <unknown>
#11 0x5617c858072b <unknown>
#12 0x5617c8584534 <unknown>
#13 0x5617c8567229 <unknown>
#14 0x5617c85850d8 <unknown>
#15 0x5617c854b61f <unknown>
#16 0x5617c85a8dd8 <unknown>
#17 0x5617c85a8fb6 <unknown>
#18 0x5617c85baaf6 <unknown>
#19 0x7f8fade9caa4 <unknown>
#20 0x7f8fadf29c3c <unknown>

2025-07-16 17:56:40,453 - INFO - üéØ [15/22] Applying to: AI Engineer - LINK: https://www.dice.com/job-detail/f647cd5e-1463-494a-a02f-7873bdbe7617
2025-07-16 17:56:58,462 - INFO -    ‚úÖ Successfully applied!
2025-07-16 17:57:07,039 - INFO - üéØ [16/22] Applying to: Python Developer - W2 - LINK: https://www.dice.com/job-detail/93f6fb5a-564c-447a-a26f-cf2df75d7cc6
2025-07-16 17:57:23,356 - ERROR -    ‚ùå Cannot click apply button: Message: element not interactable
  (Session info: chrome=138.0.7204.100); For documentation on this error, please visit: https://www.selenium.dev/documentation/webdriver/troubleshooting/errors#elementnotinteractableexception
Stacktrace:
#0 0x5617c85bb7da <unknown>
#1 0x5617c8060133 <unknown>
#2 0x5617c80b300e <unknown>
#3 0x5617c80a60ea <unknown>
#4 0x5617c80d78b2 <unknown>
#5 0x5617c80a5a6a <unknown>
#6 0x5617c80d7a7e <unknown>
#7 0x5617c80fd71c <unknown>
#8 0x5617c80d7683 <unknown>
#9 0x5617c80a3b5b <unknown>
#10 0x5617c80a4f31 <unknown>
#11 0x5617c858072b <unknown>
#12 0x5617c8584534 <unknown>
#13 0x5617c8567229 <unknown>
#14 0x5617c85850d8 <unknown>
#15 0x5617c854b61f <unknown>
#16 0x5617c85a8dd8 <unknown>
#17 0x5617c85a8fb6 <unknown>
#18 0x5617c85baaf6 <unknown>
#19 0x7f8fade9caa4 <unknown>
#20 0x7f8fadf29c3c <unknown>

2025-07-16 17:57:31,140 - INFO - üéØ [17/22] Applying to: AI Engineer ONSITE California - LINK: https://www.dice.com/job-detail/a595f03c-52e0-4efb-9e58-7b637d528921
2025-07-16 17:57:51,439 - INFO -    ‚úÖ Successfully applied!
2025-07-16 17:59:59,570 - INFO - üéØ [18/22] Applying to: Generative AI Architect :: REMOTE WITH Travel :: Fulltime Permanent - LINK: https://www.dice.com/job-detail/f311263a-be88-4035-b9dd-54afd1b3a0ba
2025-07-16 18:01:59,587 - ERROR -    ‚ùå Application failed: HTTPConnectionPool(host='localhost', port=33403): Read timed out. (read timeout=120)
2025-07-16 18:01:59,587 - ERROR - Full error for Generative AI Architect :: REMOTE WITH Travel :: Fulltime Permanent:
Traceback (most recent call last):
  File "/opt/hostedtoolcache/Python/3.10.18/x64/lib/python3.10/site-packages/urllib3/connectionpool.py", line 534, in _make_request
    response = conn.getresponse()
  File "/opt/hostedtoolcache/Python/3.10.18/x64/lib/python3.10/site-packages/urllib3/connection.py", line 565, in getresponse
    httplib_response = super().getresponse()
  File "/opt/hostedtoolcache/Python/3.10.18/x64/lib/python3.10/http/client.py", line 1375, in getresponse
    response.begin()
  File "/opt/hostedtoolcache/Python/3.10.18/x64/lib/python3.10/http/client.py", line 318, in begin
    version, status, reason = self._read_status()
  File "/opt/hostedtoolcache/Python/3.10.18/x64/lib/python3.10/http/client.py", line 279, in _read_status
    line = str(self.fp.readline(_MAXLINE + 1), "iso-8859-1")
  File "/opt/hostedtoolcache/Python/3.10.18/x64/lib/python3.10/socket.py", line 717, in readinto
    return self._sock.recv_into(b)
TimeoutError: timed out

The above exception was the direct cause of the following exception:

Traceback (most recent call last):
  File "/home/runner/work/Applier-Workflow/Applier-Workflow/scripts/src/stealth_apply.py", line 145, in easy_apply
    driver.get(job_link)
  File "/opt/hostedtoolcache/Python/3.10.18/x64/lib/python3.10/site-packages/undetected_chromedriver/__init__.py", line 496, in get_wrapped
    if self.execute_script("return navigator.webdriver"):
  File "/opt/hostedtoolcache/Python/3.10.18/x64/lib/python3.10/site-packages/selenium/webdriver/remote/webdriver.py", line 551, in execute_script
    return self.execute(command, {"script": script, "args": converted_args})["value"]
  File "/opt/hostedtoolcache/Python/3.10.18/x64/lib/python3.10/site-packages/selenium/webdriver/remote/webdriver.py", line 451, in execute
    response = cast(RemoteConnection, self.command_executor).execute(driver_command, params)
  File "/opt/hostedtoolcache/Python/3.10.18/x64/lib/python3.10/site-packages/selenium/webdriver/remote/remote_connection.py", line 404, in execute
    return self._request(command_info[0], url, body=data)
  File "/opt/hostedtoolcache/Python/3.10.18/x64/lib/python3.10/site-packages/selenium/webdriver/remote/remote_connection.py", line 428, in _request
    response = self._conn.request(method, url, body=body, headers=headers, timeout=self._client_config.timeout)
  File "/opt/hostedtoolcache/Python/3.10.18/x64/lib/python3.10/site-packages/urllib3/_request_methods.py", line 143, in request
    return self.request_encode_body(
  File "/opt/hostedtoolcache/Python/3.10.18/x64/lib/python3.10/site-packages/urllib3/_request_methods.py", line 278, in request_encode_body
    return self.urlopen(method, url, **extra_kw)
  File "/opt/hostedtoolcache/Python/3.10.18/x64/lib/python3.10/site-packages/urllib3/poolmanager.py", line 459, in urlopen
    response = conn.urlopen(method, u.request_uri, **kw)
  File "/opt/hostedtoolcache/Python/3.10.18/x64/lib/python3.10/site-packages/urllib3/connectionpool.py", line 841, in urlopen
    retries = retries.increment(
  File "/opt/hostedtoolcache/Python/3.10.18/x64/lib/python3.10/site-packages/urllib3/util/retry.py", line 474, in increment
    raise reraise(type(error), error, _stacktrace)
  File "/opt/hostedtoolcache/Python/3.10.18/x64/lib/python3.10/site-packages/urllib3/util/util.py", line 39, in reraise
    raise value
  File "/opt/hostedtoolcache/Python/3.10.18/x64/lib/python3.10/site-packages/urllib3/connectionpool.py", line 787, in urlopen
    response = self._make_request(
  File "/opt/hostedtoolcache/Python/3.10.18/x64/lib/python3.10/site-packages/urllib3/connectionpool.py", line 536, in _make_request
    self._raise_timeout(err=e, url=url, timeout_value=read_timeout)
  File "/opt/hostedtoolcache/Python/3.10.18/x64/lib/python3.10/site-packages/urllib3/connectionpool.py", line 367, in _raise_timeout
    raise ReadTimeoutError(
urllib3.exceptions.ReadTimeoutError: HTTPConnectionPool(host='localhost', port=33403): Read timed out. (read timeout=120)
2025-07-16 18:03:01,201 - INFO - üéØ [19/22] Applying to: Python Developer with Angular/React and Gen AI Exp - Mooresville, NC - LINK: https://www.dice.com/job-detail/216f68c3-53d0-4991-83ec-7e0cc1e3880c
2025-07-16 18:05:15,879 - ERROR -    ‚ùå Cannot click first NEXT button: HTTPConnectionPool(host='localhost', port=33403): Read timed out. (read timeout=120)
2025-07-16 18:07:22,691 - INFO - üéØ [20/22] Applying to: AWS Bedrock Developer with Gen AI - LINK: https://www.dice.com/job-detail/0643248d-a08c-4a14-a08a-4c93c8c70acc
2025-07-16 18:08:36,190 - ERROR -    ‚ùå Cannot click apply button: Message: element not interactable
  (Session info: chrome=138.0.7204.100); For documentation on this error, please visit: https://www.selenium.dev/documentation/webdriver/troubleshooting/errors#elementnotinteractableexception
Stacktrace:
#0 0x5617c85bb7da <unknown>
#1 0x5617c8060133 <unknown>
#2 0x5617c80b300e <unknown>
#3 0x5617c80a60ea <unknown>
#4 0x5617c80d78b2 <unknown>
#5 0x5617c80a5a6a <unknown>
#6 0x5617c80d7a7e <unknown>
#7 0x5617c80fd71c <unknown>
#8 0x5617c80d7683 <unknown>
#9 0x5617c80a3b5b <unknown>
#10 0x5617c80a4f31 <unknown>
#11 0x5617c858072b <unknown>
#12 0x5617c8584534 <unknown>
#13 0x5617c8567229 <unknown>
#14 0x5617c85850d8 <unknown>
#15 0x5617c854b61f <unknown>
#16 0x5617c85a8dd8 <unknown>
#17 0x5617c85a8fb6 <unknown>
#18 0x5617c85baaf6 <unknown>
#19 0x7f8fade9caa4 <unknown>
#20 0x7f8fadf29c3c <unknown>

2025-07-16 18:08:46,466 - INFO - üéØ [21/22] Applying to: Data Scientist(Gen AI) with Production Support - LINK: https://www.dice.com/job-detail/24442da8-8df8-4c72-9679-b780d3948fe1
2025-07-16 18:09:05,236 - ERROR -    ‚ùå Cannot click apply button: Message: element not interactable
  (Session info: chrome=138.0.7204.100); For documentation on this error, please visit: https://www.selenium.dev/documentation/webdriver/troubleshooting/errors#elementnotinteractableexception
Stacktrace:
#0 0x5617c85bb7da <unknown>
#1 0x5617c8060133 <unknown>
#2 0x5617c80b300e <unknown>
#3 0x5617c80a60ea <unknown>
#4 0x5617c80d78b2 <unknown>
#5 0x5617c80a5a6a <unknown>
#6 0x5617c80d7a7e <unknown>
#7 0x5617c80fd71c <unknown>
#8 0x5617c80d7683 <unknown>
#9 0x5617c80a3b5b <unknown>
#10 0x5617c80a4f31 <unknown>
#11 0x5617c858072b <unknown>
#12 0x5617c8584534 <unknown>
#13 0x5617c8567229 <unknown>
#14 0x5617c85850d8 <unknown>
#15 0x5617c854b61f <unknown>
#16 0x5617c85a8dd8 <unknown>
#17 0x5617c85a8fb6 <unknown>
#18 0x5617c85baaf6 <unknown>
#19 0x7f8fade9caa4 <unknown>
#20 0x7f8fadf29c3c <unknown>

2025-07-16 18:09:16,454 - INFO - üéØ [22/22] Applying to: Lead AI Data Scientist - LINK: https://www.dice.com/job-detail/51eb29dd-a6b8-4518-8977-1792ccf19c8a
2025-07-16 18:09:34,675 - ERROR -    ‚ùå Cannot click apply button: Message: element not interactable
  (Session info: chrome=138.0.7204.100); For documentation on this error, please visit: https://www.selenium.dev/documentation/webdriver/troubleshooting/errors#elementnotinteractableexception
Stacktrace:
#0 0x5617c85bb7da <unknown>
#1 0x5617c8060133 <unknown>
#2 0x5617c80b300e <unknown>
#3 0x5617c80a60ea <unknown>
#4 0x5617c80d78b2 <unknown>
#5 0x5617c80a5a6a <unknown>
#6 0x5617c80d7a7e <unknown>
#7 0x5617c80fd71c <unknown>
#8 0x5617c80d7683 <unknown>
#9 0x5617c80a3b5b <unknown>
#10 0x5617c80a4f31 <unknown>
#11 0x5617c858072b <unknown>
#12 0x5617c8584534 <unknown>
#13 0x5617c8567229 <unknown>
#14 0x5617c85850d8 <unknown>
#15 0x5617c854b61f <unknown>
#16 0x5617c85a8dd8 <unknown>
#17 0x5617c85a8fb6 <unknown>
#18 0x5617c85baaf6 <unknown>
#19 0x7f8fade9caa4 <unknown>
#20 0x7f8fadf29c3c <unknown>

2025-07-16 18:09:35,970 - INFO - üìä Processing results...
2025-07-16 18:09:35,990 - INFO - üéâ Application run completed!
2025-07-16 18:09:35,990 - INFO -    ‚úÖ Newly applied: 4
2025-07-16 18:09:35,990 - INFO -    ‚è≠Ô∏è  Already applied: 0
2025-07-16 18:09:35,990 - INFO -    ‚ùå Failed: 18
2025-07-16 18:09:35,990 - INFO -    üìä Total processed: 22
2025-07-16 18:09:35,990 - INFO -    üìÅ Total jobs in CSV: 580
2025-07-16 18:09:35,990 - INFO -    üíæ Updated: output/final_ml_jobs.csv
2025-07-16 18:09:35,990 - INFO - üîß Closing browser...
